2025-06-08 21:01:14,328 - __main__ - INFO - Data cleaning completed successfully
2025-06-08 21:02:19,818 - __main__ - ERROR - Failed to generate data report: <matplotlib.backends.backend_mixed.MixedModeRenderer object at 0x000001FDB646E330>
2025-06-09 18:42:25,399 - __main__ - INFO - Data cleaning completed successfully
2025-06-12 19:01:53,090 - __main__ - INFO - Data cleaning completed successfully
2025-06-12 19:19:07,445 - __main__ - INFO - Data cleaning completed successfully
2025-06-13 17:18:38,069 - __main__ - INFO - Data cleaning completed successfully
2025-06-14 20:33:40,741 - __main__ - INFO - Data cleaning completed successfully
2025-06-14 22:56:34,961 - __main__ - INFO - Data cleaning completed successfully
2025-06-16 22:54:26,085 - root - ERROR - Error loading claims data: 'employee_id'
2025-06-16 22:55:32,985 - __main__ - INFO - Data cleaning completed successfully
2025-07-01 16:56:33,718 - __main__ - INFO - Data cleaning completed successfully
2025-07-01 16:57:21,055 - __main__ - INFO - Data cleaning completed successfully
2025-07-02 06:53:56,694 - __main__ - INFO - Data cleaning completed successfully
2025-07-02 08:48:57,562 - __main__ - INFO - Data cleaning completed successfully
2025-07-02 09:52:37,167 - __main__ - INFO - Data cleaning completed successfully
2025-07-02 10:11:50,601 - __main__ - INFO - Data cleaning completed successfully
2025-07-02 10:30:12,813 - __main__ - INFO - Data cleaning completed successfully
2025-07-02 10:59:25,796 - __main__ - INFO - Data cleaning completed successfully
2025-07-02 11:17:45,153 - __main__ - INFO - Data cleaning completed successfully
2025-07-02 11:58:00,151 - __main__ - INFO - Data cleaning completed successfully
2025-07-02 12:06:17,141 - __main__ - INFO - Data cleaning completed successfully
2025-07-02 12:09:23,238 - __main__ - INFO - Data cleaning completed successfully
2025-07-02 12:24:15,801 - __main__ - INFO - Data cleaning completed successfully
2025-07-02 13:05:14,322 - __main__ - INFO - Data cleaning completed successfully
2025-07-02 13:25:03,552 - __main__ - INFO - Data cleaning completed successfully
2025-07-02 14:13:53,382 - __main__ - INFO - Data cleaning completed successfully
2025-07-02 14:16:17,196 - __main__ - INFO - Data cleaning completed successfully
2025-07-02 14:23:39,081 - __main__ - INFO - Data cleaning completed successfully
2025-07-02 14:44:16,502 - __main__ - INFO - Data cleaning completed successfully
2025-07-02 15:44:41,536 - __main__ - INFO - Data cleaning completed successfully
2025-07-02 15:45:39,983 - __main__ - INFO - Data cleaning completed successfully
2025-07-02 17:48:16,594 - __main__ - INFO - Data cleaning completed successfully
2025-07-02 17:59:36,272 - __main__ - INFO - Data cleaning completed successfully
2025-07-02 18:02:27,727 - __main__ - INFO - Best params for GradientBoosting: {'regressor__n_estimators': 100, 'regressor__max_depth': 3, 'regressor__learning_rate': 0.01}
2025-07-02 18:02:27,769 - __main__ - WARNING - Fraud model training failed: This ColumnTransformer instance is not fitted yet. Call 'fit' with appropriate arguments before using this estimator.
2025-07-02 18:04:35,183 - root - ERROR - Report generation failed: Could not convert string '554479' to numeric
2025-07-02 18:09:59,528 - __main__ - INFO - Data cleaning completed successfully
2025-07-02 18:10:58,980 - root - ERROR - Report generation failed: Invalid binary data format: <class 'dict'>
2025-07-02 19:12:54,896 - __main__ - INFO - Data cleaning completed successfully
2025-07-02 19:19:22,779 - __main__ - INFO - Best params for GradientBoosting: {'regressor__n_estimators': 100, 'regressor__max_depth': 3, 'regressor__learning_rate': 0.01}
2025-07-02 19:19:31,463 - __main__ - INFO - Best params for RandomForest: {'regressor__n_estimators': 50, 'regressor__min_samples_split': 5, 'regressor__max_depth': 5}
2025-07-02 19:19:43,671 - __main__ - INFO - Best params for NeuralNetwork: {'regressor__solver': 'sgd', 'regressor__hidden_layer_sizes': (50,), 'regressor__activation': 'tanh'}
2025-07-02 19:29:02,456 - __main__ - INFO - Data cleaning completed successfully
2025-07-02 19:31:00,107 - __main__ - INFO - Best params for GradientBoosting: {'regressor__n_estimators': 100, 'regressor__max_depth': 3, 'regressor__learning_rate': 0.01}
2025-07-02 19:31:23,497 - __main__ - INFO - Best params for RandomForest: {'regressor__n_estimators': 50, 'regressor__min_samples_split': 5, 'regressor__max_depth': 5}
2025-07-02 19:32:35,992 - __main__ - INFO - Best params for NeuralNetwork: {'regressor__solver': 'sgd', 'regressor__hidden_layer_sizes': (50,), 'regressor__activation': 'tanh'}
2025-07-02 20:58:19,192 - __main__ - INFO - Data cleaning completed successfully
2025-07-03 04:50:35,352 - __main__ - INFO - Data cleaning completed successfully
2025-07-03 05:59:27,709 - __main__ - INFO - Data cleaning completed successfully
2025-07-03 07:04:16,639 - root - ERROR - File processing error: Unknown format code 'f' for object of type 'str'
2025-07-03 07:04:28,773 - __main__ - INFO - Data cleaning completed successfully
2025-07-03 07:12:06,590 - root - ERROR - File processing error: Unknown format code 'f' for object of type 'str'
2025-07-03 07:12:18,814 - __main__ - INFO - Data cleaning completed successfully
2025-07-03 07:16:39,949 - __main__ - INFO - Best params for GradientBoosting: {'regressor__n_estimators': 100, 'regressor__max_depth': 3, 'regressor__learning_rate': 0.01}
2025-07-03 07:16:39,995 - __main__ - WARNING - Fraud model training failed: This ColumnTransformer instance is not fitted yet. Call 'fit' with appropriate arguments before using this estimator.
2025-07-03 07:22:23,133 - root - ERROR - File processing error: Unknown format code 'f' for object of type 'str'
2025-07-03 07:22:30,379 - __main__ - INFO - Data cleaning completed successfully
2025-07-03 07:30:56,992 - root - ERROR - File processing error: Unknown format code 'f' for object of type 'str'
2025-07-03 07:34:40,837 - root - ERROR - File processing error: Unknown format code 'f' for object of type 'str'
2025-07-03 07:46:22,361 - root - ERROR - File processing error: Unknown format code 'f' for object of type 'str'
2025-07-03 07:46:52,594 - __main__ - INFO - Data cleaning completed successfully
2025-07-03 08:33:16,688 - root - ERROR - File processing error: Unknown format code 'f' for object of type 'str'
2025-07-03 08:33:28,669 - __main__ - INFO - Data cleaning completed successfully
2025-07-03 08:49:41,837 - root - ERROR - File processing error: Unknown format code 'f' for object of type 'str'
2025-07-03 08:49:49,344 - __main__ - INFO - Data cleaning completed successfully
2025-07-03 09:03:21,600 - root - ERROR - File processing error: Unknown format code 'f' for object of type 'str'
2025-07-03 09:17:12,185 - root - ERROR - File processing error: Unknown format code 'f' for object of type 'str'
2025-07-03 09:21:11,943 - root - ERROR - File processing error: Unknown format code 'f' for object of type 'str'
2025-07-03 10:46:06,360 - root - ERROR - Error loading claims data: Error tokenizing data. C error: Expected 2 fields in line 8, saw 3

2025-07-03 10:46:41,577 - root - ERROR - Error loading claims data: Error tokenizing data. C error: Expected 2 fields in line 8, saw 3

2025-07-03 10:47:44,036 - root - ERROR - Error loading claims data: Error tokenizing data. C error: Expected 2 fields in line 8, saw 3

2025-07-03 10:51:26,907 - root - ERROR - Error loading claims data: Error tokenizing data. C error: Expected 2 fields in line 8, saw 3

2025-07-03 10:54:44,852 - root - ERROR - Error loading claims data: Error tokenizing data. C error: Expected 2 fields in line 8, saw 3

2025-07-03 11:08:00,036 - root - ERROR - Error loading claims data: Error tokenizing data. C error: Expected 2 fields in line 8, saw 3

2025-07-03 11:08:22,468 - root - ERROR - File processing error: Unknown format code 'f' for object of type 'str'
2025-07-03 11:11:23,393 - root - ERROR - Data loading failed
Traceback (most recent call last):
  File "C:\Users\dkeya\Documents\projects\the Verse\demo\app.py", line 1585, in load_real_claims_data
    df = pd.read_csv(uploaded_file, thousands=',', encoding=encoding)
         ^^^^^^^^^^^^^^^^^^^^^^^^^^^^^^^^^^^^^^^^^^^^^^^^^^^^^^^^^^^^
  File "C:\Users\dkeya\AppData\Local\Packages\PythonSoftwareFoundation.Python.3.12_qbz5n2kfra8p0\LocalCache\local-packages\Python312\site-packages\pandas\io\parsers\readers.py", line 1026, in read_csv
    return _read(filepath_or_buffer, kwds)
           ^^^^^^^^^^^^^^^^^^^^^^^^^^^^^^^
  File "C:\Users\dkeya\AppData\Local\Packages\PythonSoftwareFoundation.Python.3.12_qbz5n2kfra8p0\LocalCache\local-packages\Python312\site-packages\pandas\io\parsers\readers.py", line 620, in _read
    parser = TextFileReader(filepath_or_buffer, **kwds)
             ^^^^^^^^^^^^^^^^^^^^^^^^^^^^^^^^^^^^^^^^^^
  File "C:\Users\dkeya\AppData\Local\Packages\PythonSoftwareFoundation.Python.3.12_qbz5n2kfra8p0\LocalCache\local-packages\Python312\site-packages\pandas\io\parsers\readers.py", line 1620, in __init__
    self._engine = self._make_engine(f, self.engine)
                   ^^^^^^^^^^^^^^^^^^^^^^^^^^^^^^^^^
  File "C:\Users\dkeya\AppData\Local\Packages\PythonSoftwareFoundation.Python.3.12_qbz5n2kfra8p0\LocalCache\local-packages\Python312\site-packages\pandas\io\parsers\readers.py", line 1898, in _make_engine
    return mapping[engine](f, **self.options)
           ^^^^^^^^^^^^^^^^^^^^^^^^^^^^^^^^^^
  File "C:\Users\dkeya\AppData\Local\Packages\PythonSoftwareFoundation.Python.3.12_qbz5n2kfra8p0\LocalCache\local-packages\Python312\site-packages\pandas\io\parsers\c_parser_wrapper.py", line 93, in __init__
    self._reader = parsers.TextReader(src, **kwds)
                   ^^^^^^^^^^^^^^^^^^^^^^^^^^^^^^^
  File "parsers.pyx", line 581, in pandas._libs.parsers.TextReader.__cinit__
pandas.errors.EmptyDataError: No columns to parse from file
2025-07-03 11:11:35,374 - root - ERROR - Data loading failed
Traceback (most recent call last):
  File "C:\Users\dkeya\Documents\projects\the Verse\demo\app.py", line 1585, in load_real_claims_data
    df = pd.read_csv(uploaded_file, thousands=',', encoding=encoding)
         ^^^^^^^^^^^^^^^^^^^^^^^^^^^^^^^^^^^^^^^^^^^^^^^^^^^^^^^^^^^^
  File "C:\Users\dkeya\AppData\Local\Packages\PythonSoftwareFoundation.Python.3.12_qbz5n2kfra8p0\LocalCache\local-packages\Python312\site-packages\pandas\io\parsers\readers.py", line 1026, in read_csv
    return _read(filepath_or_buffer, kwds)
           ^^^^^^^^^^^^^^^^^^^^^^^^^^^^^^^
  File "C:\Users\dkeya\AppData\Local\Packages\PythonSoftwareFoundation.Python.3.12_qbz5n2kfra8p0\LocalCache\local-packages\Python312\site-packages\pandas\io\parsers\readers.py", line 620, in _read
    parser = TextFileReader(filepath_or_buffer, **kwds)
             ^^^^^^^^^^^^^^^^^^^^^^^^^^^^^^^^^^^^^^^^^^
  File "C:\Users\dkeya\AppData\Local\Packages\PythonSoftwareFoundation.Python.3.12_qbz5n2kfra8p0\LocalCache\local-packages\Python312\site-packages\pandas\io\parsers\readers.py", line 1620, in __init__
    self._engine = self._make_engine(f, self.engine)
                   ^^^^^^^^^^^^^^^^^^^^^^^^^^^^^^^^^
  File "C:\Users\dkeya\AppData\Local\Packages\PythonSoftwareFoundation.Python.3.12_qbz5n2kfra8p0\LocalCache\local-packages\Python312\site-packages\pandas\io\parsers\readers.py", line 1898, in _make_engine
    return mapping[engine](f, **self.options)
           ^^^^^^^^^^^^^^^^^^^^^^^^^^^^^^^^^^
  File "C:\Users\dkeya\AppData\Local\Packages\PythonSoftwareFoundation.Python.3.12_qbz5n2kfra8p0\LocalCache\local-packages\Python312\site-packages\pandas\io\parsers\c_parser_wrapper.py", line 93, in __init__
    self._reader = parsers.TextReader(src, **kwds)
                   ^^^^^^^^^^^^^^^^^^^^^^^^^^^^^^^
  File "parsers.pyx", line 581, in pandas._libs.parsers.TextReader.__cinit__
pandas.errors.EmptyDataError: No columns to parse from file
2025-07-03 11:19:35,103 - root - ERROR - File processing error: 'utf-8' codec can't decode bytes in position 15-16: invalid continuation byte
2025-07-03 11:20:41,308 - root - ERROR - File processing error: 'utf-8' codec can't decode bytes in position 15-16: invalid continuation byte
2025-07-03 11:25:29,365 - root - INFO - Renamed PROV_NAME to provider_id
2025-07-03 11:25:29,367 - root - INFO - Renamed AMOUNT to amount
2025-07-03 11:25:29,368 - root - INFO - Renamed CLAIM_PROV_DATE to date
2025-07-03 11:25:29,368 - root - INFO - Renamed CLAIM_MEMBER_NUMBER to employee_id
2025-07-03 11:25:29,368 - root - INFO - Renamed Ailment to diagnosis
2025-07-03 11:25:29,368 - root - INFO - Renamed SERVICE_DESCRIPTION to treatment
2025-07-03 11:25:29,368 - root - INFO - Renamed POL_NAME to employer
2025-07-03 11:25:29,368 - root - INFO - Renamed Department to department
2025-07-03 11:25:41,359 - __main__ - INFO - Data cleaning completed successfully
2025-07-03 11:32:31,491 - root - INFO - Renamed PROV_NAME to provider_id
2025-07-03 11:32:31,494 - root - INFO - Renamed AMOUNT to amount
2025-07-03 11:32:31,494 - root - INFO - Renamed CLAIM_PROV_DATE to date
2025-07-03 11:32:31,494 - root - INFO - Renamed CLAIM_MEMBER_NUMBER to employee_id
2025-07-03 11:32:31,494 - root - INFO - Renamed Ailment to diagnosis
2025-07-03 11:32:31,500 - root - INFO - Renamed SERVICE_DESCRIPTION to treatment
2025-07-03 11:32:31,500 - root - INFO - Renamed POL_NAME to employer
2025-07-03 11:32:31,504 - root - INFO - Renamed Department to department
2025-07-03 11:33:04,143 - __main__ - INFO - Data cleaning completed successfully
2025-07-03 13:33:13,550 - root - INFO - Renamed PROV_NAME to provider_id
2025-07-03 13:33:13,551 - root - INFO - Renamed AMOUNT to amount
2025-07-03 13:33:13,551 - root - INFO - Renamed CLAIM_PROV_DATE to date
2025-07-03 13:33:13,552 - root - INFO - Renamed CLAIM_MEMBER_NUMBER to employee_id
2025-07-03 13:33:13,552 - root - INFO - Renamed Ailment to diagnosis
2025-07-03 13:33:13,553 - root - INFO - Renamed SERVICE_DESCRIPTION to treatment
2025-07-03 13:33:13,553 - root - INFO - Renamed POL_NAME to employer
2025-07-03 13:33:13,554 - root - INFO - Renamed Department to department
2025-07-03 13:33:26,424 - __main__ - INFO - Data cleaning completed successfully
2025-07-03 13:37:19,680 - root - INFO - Renamed PROV_NAME to provider_id
2025-07-03 13:37:19,683 - root - INFO - Renamed AMOUNT to amount
2025-07-03 13:37:19,684 - root - INFO - Renamed CLAIM_PROV_DATE to date
2025-07-03 13:37:19,685 - root - INFO - Renamed CLAIM_MEMBER_NUMBER to employee_id
2025-07-03 13:37:19,686 - root - INFO - Renamed Ailment to diagnosis
2025-07-03 13:37:19,687 - root - INFO - Renamed SERVICE_DESCRIPTION to treatment
2025-07-03 13:37:19,687 - root - INFO - Renamed POL_NAME to employer
2025-07-03 13:37:19,687 - root - INFO - Renamed Department to department
2025-07-03 13:37:33,340 - __main__ - INFO - Data cleaning completed successfully
2025-07-03 13:38:27,975 - root - INFO - Renamed PROV_NAME to provider_id
2025-07-03 13:38:27,975 - root - INFO - Renamed AMOUNT to amount
2025-07-03 13:38:27,983 - root - INFO - Renamed CLAIM_PROV_DATE to date
2025-07-03 13:38:27,983 - root - INFO - Renamed CLAIM_MEMBER_NUMBER to employee_id
2025-07-03 13:38:27,983 - root - INFO - Renamed Ailment to diagnosis
2025-07-03 13:38:27,983 - root - INFO - Renamed SERVICE_DESCRIPTION to treatment
2025-07-03 13:38:27,983 - root - INFO - Renamed POL_NAME to employer
2025-07-03 13:38:27,983 - root - INFO - Renamed Department to department
2025-07-03 13:39:48,497 - __main__ - INFO - Data cleaning completed successfully
2025-07-03 13:50:08,069 - root - INFO - Renamed PROV_NAME to provider_id
2025-07-03 13:50:08,070 - root - INFO - Renamed AMOUNT to amount
2025-07-03 13:50:08,070 - root - INFO - Renamed CLAIM_PROV_DATE to date
2025-07-03 13:50:08,071 - root - INFO - Renamed CLAIM_MEMBER_NUMBER to employee_id
2025-07-03 13:50:08,071 - root - INFO - Renamed Ailment to diagnosis
2025-07-03 13:50:08,071 - root - INFO - Renamed SERVICE_DESCRIPTION to treatment
2025-07-03 13:50:08,072 - root - INFO - Renamed POL_NAME to employer
2025-07-03 13:50:08,072 - root - INFO - Renamed Department to department
2025-07-03 14:19:40,466 - root - INFO - Renamed PROV_NAME to provider_id
2025-07-03 14:19:40,474 - root - INFO - Renamed AMOUNT to amount
2025-07-03 14:19:40,474 - root - INFO - Renamed CLAIM_PROV_DATE to date
2025-07-03 14:19:40,474 - root - INFO - Renamed CLAIM_MEMBER_NUMBER to employee_id
2025-07-03 14:19:40,474 - root - INFO - Renamed Ailment to diagnosis
2025-07-03 14:19:40,474 - root - INFO - Renamed SERVICE_DESCRIPTION to treatment
2025-07-03 14:19:40,474 - root - INFO - Renamed POL_NAME to employer
2025-07-03 14:19:40,482 - root - INFO - Renamed Department to department
2025-07-03 14:27:53,533 - __main__ - INFO - Data cleaning completed successfully
2025-07-03 14:36:03,797 - root - INFO - Renamed PROV_NAME to provider_id
2025-07-03 14:36:03,806 - root - INFO - Renamed AMOUNT to amount
2025-07-03 14:36:03,806 - root - INFO - Renamed CLAIM_PROV_DATE to date
2025-07-03 14:36:03,806 - root - INFO - Renamed CLAIM_MEMBER_NUMBER to employee_id
2025-07-03 14:36:03,806 - root - INFO - Renamed Ailment to diagnosis
2025-07-03 14:36:03,806 - root - INFO - Renamed SERVICE_DESCRIPTION to treatment
2025-07-03 14:36:03,806 - root - INFO - Renamed POL_NAME to employer
2025-07-03 14:36:03,806 - root - INFO - Renamed Department to department
2025-07-03 14:36:10,469 - __main__ - INFO - Data cleaning completed successfully
2025-07-03 14:46:42,201 - root - INFO - Renamed PROV_NAME to provider_id
2025-07-03 14:46:42,202 - root - INFO - Renamed AMOUNT to amount
2025-07-03 14:46:42,202 - root - INFO - Renamed CLAIM_PROV_DATE to date
2025-07-03 14:46:42,207 - root - INFO - Renamed CLAIM_MEMBER_NUMBER to employee_id
2025-07-03 14:46:42,207 - root - INFO - Renamed Ailment to diagnosis
2025-07-03 14:46:42,207 - root - INFO - Renamed SERVICE_DESCRIPTION to treatment
2025-07-03 14:46:42,207 - root - INFO - Renamed POL_NAME to employer
2025-07-03 14:46:42,215 - root - INFO - Renamed Department to department
2025-07-03 14:46:47,010 - __main__ - INFO - Data cleaning completed successfully
2025-07-07 06:50:44,348 - root - INFO - Renamed PROV_NAME to provider_id
2025-07-07 06:50:44,348 - root - INFO - Renamed AMOUNT to amount
2025-07-07 06:50:44,348 - root - INFO - Renamed CLAIM_PROV_DATE to date
2025-07-07 06:50:44,348 - root - INFO - Renamed CLAIM_MEMBER_NUMBER to employee_id
2025-07-07 06:50:44,348 - root - INFO - Renamed Ailment to diagnosis
2025-07-07 06:50:44,348 - root - INFO - Renamed SERVICE_DESCRIPTION to treatment
2025-07-07 06:50:44,348 - root - INFO - Renamed POL_NAME to employer
2025-07-07 06:50:44,348 - root - INFO - Renamed Department to department
2025-07-07 06:51:21,804 - __main__ - INFO - Data cleaning completed successfully
2025-07-07 06:57:24,030 - root - INFO - Renamed PROV_NAME to provider_id
2025-07-07 06:57:24,030 - root - INFO - Renamed AMOUNT to amount
2025-07-07 06:57:24,030 - root - INFO - Renamed CLAIM_PROV_DATE to date
2025-07-07 06:57:24,030 - root - INFO - Renamed CLAIM_MEMBER_NUMBER to employee_id
2025-07-07 06:57:24,035 - root - INFO - Renamed Ailment to diagnosis
2025-07-07 06:57:24,037 - root - INFO - Renamed SERVICE_DESCRIPTION to treatment
2025-07-07 06:57:24,038 - root - INFO - Renamed POL_NAME to employer
2025-07-07 06:57:24,039 - root - INFO - Renamed Department to department
2025-07-07 06:57:42,474 - __main__ - INFO - Data cleaning completed successfully
2025-07-07 06:58:58,679 - root - ERROR - Fraud detection failed: Failed to add fraud_flag column
2025-07-07 07:09:53,915 - root - INFO - Renamed PROV_NAME to provider_id
2025-07-07 07:09:53,916 - root - INFO - Renamed AMOUNT to amount
2025-07-07 07:09:53,917 - root - INFO - Renamed CLAIM_PROV_DATE to date
2025-07-07 07:09:53,917 - root - INFO - Renamed CLAIM_MEMBER_NUMBER to employee_id
2025-07-07 07:09:53,917 - root - INFO - Renamed Ailment to diagnosis
2025-07-07 07:09:53,917 - root - INFO - Renamed SERVICE_DESCRIPTION to treatment
2025-07-07 07:09:53,918 - root - INFO - Renamed POL_NAME to employer
2025-07-07 07:09:53,919 - root - INFO - Renamed Department to department
2025-07-07 07:14:33,738 - __main__ - INFO - Data cleaning completed successfully
2025-07-07 07:44:13,859 - root - ERROR - Fraud detection failed: Failed to add fraud_flag column
2025-07-07 07:55:30,447 - root - INFO - Renamed PROV_NAME to provider_id
2025-07-07 07:55:30,447 - root - INFO - Renamed AMOUNT to amount
2025-07-07 07:55:30,448 - root - INFO - Renamed CLAIM_PROV_DATE to date
2025-07-07 07:55:30,448 - root - INFO - Renamed CLAIM_MEMBER_NUMBER to employee_id
2025-07-07 07:55:30,449 - root - INFO - Renamed Ailment to diagnosis
2025-07-07 07:55:30,449 - root - INFO - Renamed SERVICE_DESCRIPTION to treatment
2025-07-07 07:55:30,450 - root - INFO - Renamed POL_NAME to employer
2025-07-07 07:55:30,450 - root - INFO - Renamed Department to department
2025-07-07 07:56:38,325 - root - INFO - Renamed PROV_NAME to provider_id
2025-07-07 07:56:38,327 - root - INFO - Renamed AMOUNT to amount
2025-07-07 07:56:38,329 - root - INFO - Renamed CLAIM_PROV_DATE to date
2025-07-07 07:56:38,331 - root - INFO - Renamed CLAIM_MEMBER_NUMBER to employee_id
2025-07-07 07:56:38,332 - root - INFO - Renamed Ailment to diagnosis
2025-07-07 07:56:38,332 - root - INFO - Renamed SERVICE_DESCRIPTION to treatment
2025-07-07 07:56:38,333 - root - INFO - Renamed POL_NAME to employer
2025-07-07 07:56:38,334 - root - INFO - Renamed Department to department
2025-07-07 08:09:48,379 - root - ERROR - Data loading failed
Traceback (most recent call last):
  File "C:\Users\dkeya\AppData\Local\Packages\PythonSoftwareFoundation.Python.3.12_qbz5n2kfra8p0\LocalCache\local-packages\Python312\site-packages\pandas\compat\_optional.py", line 135, in import_optional_dependency
    module = importlib.import_module(name)
             ^^^^^^^^^^^^^^^^^^^^^^^^^^^^^
  File "C:\Program Files\WindowsApps\PythonSoftwareFoundation.Python.3.12_3.12.2800.0_x64__qbz5n2kfra8p0\Lib\importlib\__init__.py", line 90, in import_module
    return _bootstrap._gcd_import(name[level:], package, level)
           ^^^^^^^^^^^^^^^^^^^^^^^^^^^^^^^^^^^^^^^^^^^^^^^^^^^^
  File "<frozen importlib._bootstrap>", line 1387, in _gcd_import
  File "<frozen importlib._bootstrap>", line 1360, in _find_and_load
  File "<frozen importlib._bootstrap>", line 1324, in _find_and_load_unlocked
ModuleNotFoundError: No module named 'xlrd'

During handling of the above exception, another exception occurred:

Traceback (most recent call last):
  File "C:\Users\dkeya\Documents\projects\the Verse\demo\app.py", line 1591, in load_real_claims_data
    df = pd.read_excel(uploaded_file)
         ^^^^^^^^^^^^^^^^^^^^^^^^^^^^
  File "C:\Users\dkeya\AppData\Local\Packages\PythonSoftwareFoundation.Python.3.12_qbz5n2kfra8p0\LocalCache\local-packages\Python312\site-packages\pandas\io\excel\_base.py", line 495, in read_excel
    io = ExcelFile(
         ^^^^^^^^^^
  File "C:\Users\dkeya\AppData\Local\Packages\PythonSoftwareFoundation.Python.3.12_qbz5n2kfra8p0\LocalCache\local-packages\Python312\site-packages\pandas\io\excel\_base.py", line 1567, in __init__
    self._reader = self._engines[engine](
                   ^^^^^^^^^^^^^^^^^^^^^^
  File "C:\Users\dkeya\AppData\Local\Packages\PythonSoftwareFoundation.Python.3.12_qbz5n2kfra8p0\LocalCache\local-packages\Python312\site-packages\pandas\io\excel\_xlrd.py", line 45, in __init__
    import_optional_dependency("xlrd", extra=err_msg)
  File "C:\Users\dkeya\AppData\Local\Packages\PythonSoftwareFoundation.Python.3.12_qbz5n2kfra8p0\LocalCache\local-packages\Python312\site-packages\pandas\compat\_optional.py", line 138, in import_optional_dependency
    raise ImportError(msg)
ImportError: Missing optional dependency 'xlrd'. Install xlrd >= 2.0.1 for xls Excel support Use pip or conda to install xlrd.
2025-07-07 08:10:42,232 - root - INFO - Renamed PROV_NAME to provider_id
2025-07-07 08:10:42,232 - root - INFO - Renamed AMOUNT to amount
2025-07-07 08:10:42,232 - root - INFO - Renamed CLAIM_PROV_DATE to date
2025-07-07 08:10:42,232 - root - INFO - Renamed CLAIM_MEMBER_NUMBER to employee_id
2025-07-07 08:10:42,240 - root - INFO - Renamed Ailment to diagnosis
2025-07-07 08:10:42,240 - root - INFO - Renamed SERVICE_DESCRIPTION to treatment
2025-07-07 08:10:42,240 - root - INFO - Renamed POL_NAME to employer
2025-07-07 08:10:42,240 - root - INFO - Renamed Department to department
2025-07-07 08:22:27,278 - root - INFO - Renamed PROV_NAME to provider_id
2025-07-07 08:22:27,294 - root - INFO - Renamed AMOUNT to amount
2025-07-07 08:22:27,310 - root - INFO - Renamed CLAIM_PROV_DATE to date
2025-07-07 08:22:27,360 - root - INFO - Renamed CLAIM_MEMBER_NUMBER to employee_id
2025-07-07 08:22:27,375 - root - INFO - Renamed Ailment to diagnosis
2025-07-07 08:22:27,399 - root - INFO - Renamed SERVICE_DESCRIPTION to treatment
2025-07-07 08:22:27,414 - root - INFO - Renamed POL_NAME to employer
2025-07-07 08:22:27,414 - root - INFO - Renamed Department to department
2025-07-07 08:38:27,893 - root - INFO - Renamed PROV_NAME to provider_id
2025-07-07 08:38:27,893 - root - INFO - Renamed AMOUNT to amount
2025-07-07 08:38:27,893 - root - INFO - Renamed CLAIM_PROV_DATE to date
2025-07-07 08:38:27,893 - root - INFO - Renamed CLAIM_MEMBER_NUMBER to employee_id
2025-07-07 08:38:27,893 - root - INFO - Renamed Ailment to diagnosis
2025-07-07 08:38:27,893 - root - INFO - Renamed SERVICE_DESCRIPTION to treatment
2025-07-07 08:38:27,900 - root - INFO - Renamed POL_NAME to employer
2025-07-07 08:39:55,739 - __main__ - INFO - Data cleaning completed successfully
2025-07-07 08:43:27,892 - asyncio - ERROR - Task exception was never retrieved
future: <Task finished name='Task-902' coro=<WebSocketProtocol13.write_message.<locals>.wrapper() done, defined at C:\Users\dkeya\AppData\Local\Packages\PythonSoftwareFoundation.Python.3.12_qbz5n2kfra8p0\LocalCache\local-packages\Python312\site-packages\tornado\websocket.py:1086> exception=WebSocketClosedError()>
Traceback (most recent call last):
  File "C:\Users\dkeya\AppData\Local\Packages\PythonSoftwareFoundation.Python.3.12_qbz5n2kfra8p0\LocalCache\local-packages\Python312\site-packages\tornado\websocket.py", line 1088, in wrapper
    await fut
tornado.iostream.StreamClosedError: Stream is closed

During handling of the above exception, another exception occurred:

Traceback (most recent call last):
  File "C:\Users\dkeya\AppData\Local\Packages\PythonSoftwareFoundation.Python.3.12_qbz5n2kfra8p0\LocalCache\local-packages\Python312\site-packages\tornado\websocket.py", line 1090, in wrapper
    raise WebSocketClosedError()
tornado.websocket.WebSocketClosedError
2025-07-07 08:43:27,907 - asyncio - ERROR - Task exception was never retrieved
future: <Task finished name='Task-905' coro=<WebSocketProtocol13.write_message.<locals>.wrapper() done, defined at C:\Users\dkeya\AppData\Local\Packages\PythonSoftwareFoundation.Python.3.12_qbz5n2kfra8p0\LocalCache\local-packages\Python312\site-packages\tornado\websocket.py:1086> exception=WebSocketClosedError()>
Traceback (most recent call last):
  File "C:\Users\dkeya\AppData\Local\Packages\PythonSoftwareFoundation.Python.3.12_qbz5n2kfra8p0\LocalCache\local-packages\Python312\site-packages\tornado\websocket.py", line 1088, in wrapper
    await fut
tornado.iostream.StreamClosedError: Stream is closed

During handling of the above exception, another exception occurred:

Traceback (most recent call last):
  File "C:\Users\dkeya\AppData\Local\Packages\PythonSoftwareFoundation.Python.3.12_qbz5n2kfra8p0\LocalCache\local-packages\Python312\site-packages\tornado\websocket.py", line 1090, in wrapper
    raise WebSocketClosedError()
tornado.websocket.WebSocketClosedError
2025-07-07 08:43:27,908 - asyncio - ERROR - Task exception was never retrieved
future: <Task finished name='Task-908' coro=<WebSocketProtocol13.write_message.<locals>.wrapper() done, defined at C:\Users\dkeya\AppData\Local\Packages\PythonSoftwareFoundation.Python.3.12_qbz5n2kfra8p0\LocalCache\local-packages\Python312\site-packages\tornado\websocket.py:1086> exception=WebSocketClosedError()>
Traceback (most recent call last):
  File "C:\Users\dkeya\AppData\Local\Packages\PythonSoftwareFoundation.Python.3.12_qbz5n2kfra8p0\LocalCache\local-packages\Python312\site-packages\tornado\websocket.py", line 1088, in wrapper
    await fut
tornado.iostream.StreamClosedError: Stream is closed

During handling of the above exception, another exception occurred:

Traceback (most recent call last):
  File "C:\Users\dkeya\AppData\Local\Packages\PythonSoftwareFoundation.Python.3.12_qbz5n2kfra8p0\LocalCache\local-packages\Python312\site-packages\tornado\websocket.py", line 1090, in wrapper
    raise WebSocketClosedError()
tornado.websocket.WebSocketClosedError
2025-07-07 08:43:27,909 - asyncio - ERROR - Task exception was never retrieved
future: <Task finished name='Task-911' coro=<WebSocketProtocol13.write_message.<locals>.wrapper() done, defined at C:\Users\dkeya\AppData\Local\Packages\PythonSoftwareFoundation.Python.3.12_qbz5n2kfra8p0\LocalCache\local-packages\Python312\site-packages\tornado\websocket.py:1086> exception=WebSocketClosedError()>
Traceback (most recent call last):
  File "C:\Users\dkeya\AppData\Local\Packages\PythonSoftwareFoundation.Python.3.12_qbz5n2kfra8p0\LocalCache\local-packages\Python312\site-packages\tornado\websocket.py", line 1088, in wrapper
    await fut
tornado.iostream.StreamClosedError: Stream is closed

During handling of the above exception, another exception occurred:

Traceback (most recent call last):
  File "C:\Users\dkeya\AppData\Local\Packages\PythonSoftwareFoundation.Python.3.12_qbz5n2kfra8p0\LocalCache\local-packages\Python312\site-packages\tornado\websocket.py", line 1090, in wrapper
    raise WebSocketClosedError()
tornado.websocket.WebSocketClosedError
2025-07-07 08:43:27,910 - asyncio - ERROR - Task exception was never retrieved
future: <Task finished name='Task-914' coro=<WebSocketProtocol13.write_message.<locals>.wrapper() done, defined at C:\Users\dkeya\AppData\Local\Packages\PythonSoftwareFoundation.Python.3.12_qbz5n2kfra8p0\LocalCache\local-packages\Python312\site-packages\tornado\websocket.py:1086> exception=WebSocketClosedError()>
Traceback (most recent call last):
  File "C:\Users\dkeya\AppData\Local\Packages\PythonSoftwareFoundation.Python.3.12_qbz5n2kfra8p0\LocalCache\local-packages\Python312\site-packages\tornado\websocket.py", line 1088, in wrapper
    await fut
tornado.iostream.StreamClosedError: Stream is closed

During handling of the above exception, another exception occurred:

Traceback (most recent call last):
  File "C:\Users\dkeya\AppData\Local\Packages\PythonSoftwareFoundation.Python.3.12_qbz5n2kfra8p0\LocalCache\local-packages\Python312\site-packages\tornado\websocket.py", line 1090, in wrapper
    raise WebSocketClosedError()
tornado.websocket.WebSocketClosedError
2025-07-07 08:43:27,910 - asyncio - ERROR - Task exception was never retrieved
future: <Task finished name='Task-917' coro=<WebSocketProtocol13.write_message.<locals>.wrapper() done, defined at C:\Users\dkeya\AppData\Local\Packages\PythonSoftwareFoundation.Python.3.12_qbz5n2kfra8p0\LocalCache\local-packages\Python312\site-packages\tornado\websocket.py:1086> exception=WebSocketClosedError()>
Traceback (most recent call last):
  File "C:\Users\dkeya\AppData\Local\Packages\PythonSoftwareFoundation.Python.3.12_qbz5n2kfra8p0\LocalCache\local-packages\Python312\site-packages\tornado\websocket.py", line 1088, in wrapper
    await fut
tornado.iostream.StreamClosedError: Stream is closed

During handling of the above exception, another exception occurred:

Traceback (most recent call last):
  File "C:\Users\dkeya\AppData\Local\Packages\PythonSoftwareFoundation.Python.3.12_qbz5n2kfra8p0\LocalCache\local-packages\Python312\site-packages\tornado\websocket.py", line 1090, in wrapper
    raise WebSocketClosedError()
tornado.websocket.WebSocketClosedError
2025-07-07 08:43:27,911 - asyncio - ERROR - Task exception was never retrieved
future: <Task finished name='Task-920' coro=<WebSocketProtocol13.write_message.<locals>.wrapper() done, defined at C:\Users\dkeya\AppData\Local\Packages\PythonSoftwareFoundation.Python.3.12_qbz5n2kfra8p0\LocalCache\local-packages\Python312\site-packages\tornado\websocket.py:1086> exception=WebSocketClosedError()>
Traceback (most recent call last):
  File "C:\Users\dkeya\AppData\Local\Packages\PythonSoftwareFoundation.Python.3.12_qbz5n2kfra8p0\LocalCache\local-packages\Python312\site-packages\tornado\websocket.py", line 1088, in wrapper
    await fut
tornado.iostream.StreamClosedError: Stream is closed

During handling of the above exception, another exception occurred:

Traceback (most recent call last):
  File "C:\Users\dkeya\AppData\Local\Packages\PythonSoftwareFoundation.Python.3.12_qbz5n2kfra8p0\LocalCache\local-packages\Python312\site-packages\tornado\websocket.py", line 1090, in wrapper
    raise WebSocketClosedError()
tornado.websocket.WebSocketClosedError
2025-07-07 08:43:27,911 - asyncio - ERROR - Task exception was never retrieved
future: <Task finished name='Task-923' coro=<WebSocketProtocol13.write_message.<locals>.wrapper() done, defined at C:\Users\dkeya\AppData\Local\Packages\PythonSoftwareFoundation.Python.3.12_qbz5n2kfra8p0\LocalCache\local-packages\Python312\site-packages\tornado\websocket.py:1086> exception=WebSocketClosedError()>
Traceback (most recent call last):
  File "C:\Users\dkeya\AppData\Local\Packages\PythonSoftwareFoundation.Python.3.12_qbz5n2kfra8p0\LocalCache\local-packages\Python312\site-packages\tornado\websocket.py", line 1088, in wrapper
    await fut
tornado.iostream.StreamClosedError: Stream is closed

During handling of the above exception, another exception occurred:

Traceback (most recent call last):
  File "C:\Users\dkeya\AppData\Local\Packages\PythonSoftwareFoundation.Python.3.12_qbz5n2kfra8p0\LocalCache\local-packages\Python312\site-packages\tornado\websocket.py", line 1090, in wrapper
    raise WebSocketClosedError()
tornado.websocket.WebSocketClosedError
2025-07-07 08:43:27,912 - asyncio - ERROR - Task exception was never retrieved
future: <Task finished name='Task-926' coro=<WebSocketProtocol13.write_message.<locals>.wrapper() done, defined at C:\Users\dkeya\AppData\Local\Packages\PythonSoftwareFoundation.Python.3.12_qbz5n2kfra8p0\LocalCache\local-packages\Python312\site-packages\tornado\websocket.py:1086> exception=WebSocketClosedError()>
Traceback (most recent call last):
  File "C:\Users\dkeya\AppData\Local\Packages\PythonSoftwareFoundation.Python.3.12_qbz5n2kfra8p0\LocalCache\local-packages\Python312\site-packages\tornado\websocket.py", line 1088, in wrapper
    await fut
tornado.iostream.StreamClosedError: Stream is closed

During handling of the above exception, another exception occurred:

Traceback (most recent call last):
  File "C:\Users\dkeya\AppData\Local\Packages\PythonSoftwareFoundation.Python.3.12_qbz5n2kfra8p0\LocalCache\local-packages\Python312\site-packages\tornado\websocket.py", line 1090, in wrapper
    raise WebSocketClosedError()
tornado.websocket.WebSocketClosedError
2025-07-07 08:43:27,912 - asyncio - ERROR - Task exception was never retrieved
future: <Task finished name='Task-929' coro=<WebSocketProtocol13.write_message.<locals>.wrapper() done, defined at C:\Users\dkeya\AppData\Local\Packages\PythonSoftwareFoundation.Python.3.12_qbz5n2kfra8p0\LocalCache\local-packages\Python312\site-packages\tornado\websocket.py:1086> exception=WebSocketClosedError()>
Traceback (most recent call last):
  File "C:\Users\dkeya\AppData\Local\Packages\PythonSoftwareFoundation.Python.3.12_qbz5n2kfra8p0\LocalCache\local-packages\Python312\site-packages\tornado\websocket.py", line 1088, in wrapper
    await fut
tornado.iostream.StreamClosedError: Stream is closed

During handling of the above exception, another exception occurred:

Traceback (most recent call last):
  File "C:\Users\dkeya\AppData\Local\Packages\PythonSoftwareFoundation.Python.3.12_qbz5n2kfra8p0\LocalCache\local-packages\Python312\site-packages\tornado\websocket.py", line 1090, in wrapper
    raise WebSocketClosedError()
tornado.websocket.WebSocketClosedError
2025-07-07 08:43:27,913 - asyncio - ERROR - Task exception was never retrieved
future: <Task finished name='Task-932' coro=<WebSocketProtocol13.write_message.<locals>.wrapper() done, defined at C:\Users\dkeya\AppData\Local\Packages\PythonSoftwareFoundation.Python.3.12_qbz5n2kfra8p0\LocalCache\local-packages\Python312\site-packages\tornado\websocket.py:1086> exception=WebSocketClosedError()>
Traceback (most recent call last):
  File "C:\Users\dkeya\AppData\Local\Packages\PythonSoftwareFoundation.Python.3.12_qbz5n2kfra8p0\LocalCache\local-packages\Python312\site-packages\tornado\websocket.py", line 1088, in wrapper
    await fut
tornado.iostream.StreamClosedError: Stream is closed

During handling of the above exception, another exception occurred:

Traceback (most recent call last):
  File "C:\Users\dkeya\AppData\Local\Packages\PythonSoftwareFoundation.Python.3.12_qbz5n2kfra8p0\LocalCache\local-packages\Python312\site-packages\tornado\websocket.py", line 1090, in wrapper
    raise WebSocketClosedError()
tornado.websocket.WebSocketClosedError
2025-07-07 08:43:27,922 - asyncio - ERROR - Task exception was never retrieved
future: <Task finished name='Task-935' coro=<WebSocketProtocol13.write_message.<locals>.wrapper() done, defined at C:\Users\dkeya\AppData\Local\Packages\PythonSoftwareFoundation.Python.3.12_qbz5n2kfra8p0\LocalCache\local-packages\Python312\site-packages\tornado\websocket.py:1086> exception=WebSocketClosedError()>
Traceback (most recent call last):
  File "C:\Users\dkeya\AppData\Local\Packages\PythonSoftwareFoundation.Python.3.12_qbz5n2kfra8p0\LocalCache\local-packages\Python312\site-packages\tornado\websocket.py", line 1088, in wrapper
    await fut
tornado.iostream.StreamClosedError: Stream is closed

During handling of the above exception, another exception occurred:

Traceback (most recent call last):
  File "C:\Users\dkeya\AppData\Local\Packages\PythonSoftwareFoundation.Python.3.12_qbz5n2kfra8p0\LocalCache\local-packages\Python312\site-packages\tornado\websocket.py", line 1090, in wrapper
    raise WebSocketClosedError()
tornado.websocket.WebSocketClosedError
2025-07-07 08:43:27,925 - asyncio - ERROR - Task exception was never retrieved
future: <Task finished name='Task-938' coro=<WebSocketProtocol13.write_message.<locals>.wrapper() done, defined at C:\Users\dkeya\AppData\Local\Packages\PythonSoftwareFoundation.Python.3.12_qbz5n2kfra8p0\LocalCache\local-packages\Python312\site-packages\tornado\websocket.py:1086> exception=WebSocketClosedError()>
Traceback (most recent call last):
  File "C:\Users\dkeya\AppData\Local\Packages\PythonSoftwareFoundation.Python.3.12_qbz5n2kfra8p0\LocalCache\local-packages\Python312\site-packages\tornado\websocket.py", line 1088, in wrapper
    await fut
tornado.iostream.StreamClosedError: Stream is closed

During handling of the above exception, another exception occurred:

Traceback (most recent call last):
  File "C:\Users\dkeya\AppData\Local\Packages\PythonSoftwareFoundation.Python.3.12_qbz5n2kfra8p0\LocalCache\local-packages\Python312\site-packages\tornado\websocket.py", line 1090, in wrapper
    raise WebSocketClosedError()
tornado.websocket.WebSocketClosedError
2025-07-07 08:43:27,925 - asyncio - ERROR - Task exception was never retrieved
future: <Task finished name='Task-941' coro=<WebSocketProtocol13.write_message.<locals>.wrapper() done, defined at C:\Users\dkeya\AppData\Local\Packages\PythonSoftwareFoundation.Python.3.12_qbz5n2kfra8p0\LocalCache\local-packages\Python312\site-packages\tornado\websocket.py:1086> exception=WebSocketClosedError()>
Traceback (most recent call last):
  File "C:\Users\dkeya\AppData\Local\Packages\PythonSoftwareFoundation.Python.3.12_qbz5n2kfra8p0\LocalCache\local-packages\Python312\site-packages\tornado\websocket.py", line 1088, in wrapper
    await fut
tornado.iostream.StreamClosedError: Stream is closed

During handling of the above exception, another exception occurred:

Traceback (most recent call last):
  File "C:\Users\dkeya\AppData\Local\Packages\PythonSoftwareFoundation.Python.3.12_qbz5n2kfra8p0\LocalCache\local-packages\Python312\site-packages\tornado\websocket.py", line 1090, in wrapper
    raise WebSocketClosedError()
tornado.websocket.WebSocketClosedError
2025-07-07 08:43:27,925 - asyncio - ERROR - Task exception was never retrieved
future: <Task finished name='Task-944' coro=<WebSocketProtocol13.write_message.<locals>.wrapper() done, defined at C:\Users\dkeya\AppData\Local\Packages\PythonSoftwareFoundation.Python.3.12_qbz5n2kfra8p0\LocalCache\local-packages\Python312\site-packages\tornado\websocket.py:1086> exception=WebSocketClosedError()>
Traceback (most recent call last):
  File "C:\Users\dkeya\AppData\Local\Packages\PythonSoftwareFoundation.Python.3.12_qbz5n2kfra8p0\LocalCache\local-packages\Python312\site-packages\tornado\websocket.py", line 1088, in wrapper
    await fut
tornado.iostream.StreamClosedError: Stream is closed

During handling of the above exception, another exception occurred:

Traceback (most recent call last):
  File "C:\Users\dkeya\AppData\Local\Packages\PythonSoftwareFoundation.Python.3.12_qbz5n2kfra8p0\LocalCache\local-packages\Python312\site-packages\tornado\websocket.py", line 1090, in wrapper
    raise WebSocketClosedError()
tornado.websocket.WebSocketClosedError
2025-07-07 08:43:27,929 - asyncio - ERROR - Task exception was never retrieved
future: <Task finished name='Task-948' coro=<WebSocketProtocol13.write_message.<locals>.wrapper() done, defined at C:\Users\dkeya\AppData\Local\Packages\PythonSoftwareFoundation.Python.3.12_qbz5n2kfra8p0\LocalCache\local-packages\Python312\site-packages\tornado\websocket.py:1086> exception=WebSocketClosedError()>
Traceback (most recent call last):
  File "C:\Users\dkeya\AppData\Local\Packages\PythonSoftwareFoundation.Python.3.12_qbz5n2kfra8p0\LocalCache\local-packages\Python312\site-packages\tornado\websocket.py", line 1088, in wrapper
    await fut
tornado.iostream.StreamClosedError: Stream is closed

During handling of the above exception, another exception occurred:

Traceback (most recent call last):
  File "C:\Users\dkeya\AppData\Local\Packages\PythonSoftwareFoundation.Python.3.12_qbz5n2kfra8p0\LocalCache\local-packages\Python312\site-packages\tornado\websocket.py", line 1090, in wrapper
    raise WebSocketClosedError()
tornado.websocket.WebSocketClosedError
2025-07-07 08:43:27,930 - asyncio - ERROR - Task exception was never retrieved
future: <Task finished name='Task-949' coro=<WebSocketProtocol13.write_message.<locals>.wrapper() done, defined at C:\Users\dkeya\AppData\Local\Packages\PythonSoftwareFoundation.Python.3.12_qbz5n2kfra8p0\LocalCache\local-packages\Python312\site-packages\tornado\websocket.py:1086> exception=WebSocketClosedError()>
Traceback (most recent call last):
  File "C:\Users\dkeya\AppData\Local\Packages\PythonSoftwareFoundation.Python.3.12_qbz5n2kfra8p0\LocalCache\local-packages\Python312\site-packages\tornado\websocket.py", line 1088, in wrapper
    await fut
tornado.iostream.StreamClosedError: Stream is closed

During handling of the above exception, another exception occurred:

Traceback (most recent call last):
  File "C:\Users\dkeya\AppData\Local\Packages\PythonSoftwareFoundation.Python.3.12_qbz5n2kfra8p0\LocalCache\local-packages\Python312\site-packages\tornado\websocket.py", line 1090, in wrapper
    raise WebSocketClosedError()
tornado.websocket.WebSocketClosedError
2025-07-07 08:48:40,741 - root - INFO - Renamed PROV_NAME to provider_id
2025-07-07 08:48:40,741 - root - INFO - Renamed AMOUNT to amount
2025-07-07 08:48:40,741 - root - INFO - Renamed CLAIM_PROV_DATE to date
2025-07-07 08:48:40,749 - root - INFO - Renamed CLAIM_MEMBER_NUMBER to employee_id
2025-07-07 08:48:40,750 - root - INFO - Renamed Ailment to diagnosis
2025-07-07 08:48:40,758 - root - INFO - Renamed SERVICE_DESCRIPTION to treatment
2025-07-07 08:48:40,758 - root - INFO - Renamed POL_NAME to employer
2025-07-07 08:52:04,941 - __main__ - INFO - Data cleaning completed successfully
2025-07-07 08:55:42,443 - asyncio - ERROR - Task exception was never retrieved
future: <Task finished name='Task-1037' coro=<WebSocketProtocol13.write_message.<locals>.wrapper() done, defined at C:\Users\dkeya\AppData\Local\Packages\PythonSoftwareFoundation.Python.3.12_qbz5n2kfra8p0\LocalCache\local-packages\Python312\site-packages\tornado\websocket.py:1086> exception=WebSocketClosedError()>
Traceback (most recent call last):
  File "C:\Users\dkeya\AppData\Local\Packages\PythonSoftwareFoundation.Python.3.12_qbz5n2kfra8p0\LocalCache\local-packages\Python312\site-packages\tornado\websocket.py", line 1088, in wrapper
    await fut
tornado.iostream.StreamClosedError: Stream is closed

During handling of the above exception, another exception occurred:

Traceback (most recent call last):
  File "C:\Users\dkeya\AppData\Local\Packages\PythonSoftwareFoundation.Python.3.12_qbz5n2kfra8p0\LocalCache\local-packages\Python312\site-packages\tornado\websocket.py", line 1090, in wrapper
    raise WebSocketClosedError()
tornado.websocket.WebSocketClosedError
2025-07-07 08:55:42,445 - asyncio - ERROR - Task exception was never retrieved
future: <Task finished name='Task-1040' coro=<WebSocketProtocol13.write_message.<locals>.wrapper() done, defined at C:\Users\dkeya\AppData\Local\Packages\PythonSoftwareFoundation.Python.3.12_qbz5n2kfra8p0\LocalCache\local-packages\Python312\site-packages\tornado\websocket.py:1086> exception=WebSocketClosedError()>
Traceback (most recent call last):
  File "C:\Users\dkeya\AppData\Local\Packages\PythonSoftwareFoundation.Python.3.12_qbz5n2kfra8p0\LocalCache\local-packages\Python312\site-packages\tornado\websocket.py", line 1088, in wrapper
    await fut
tornado.iostream.StreamClosedError: Stream is closed

During handling of the above exception, another exception occurred:

Traceback (most recent call last):
  File "C:\Users\dkeya\AppData\Local\Packages\PythonSoftwareFoundation.Python.3.12_qbz5n2kfra8p0\LocalCache\local-packages\Python312\site-packages\tornado\websocket.py", line 1090, in wrapper
    raise WebSocketClosedError()
tornado.websocket.WebSocketClosedError
2025-07-07 08:55:42,446 - asyncio - ERROR - Task exception was never retrieved
future: <Task finished name='Task-1044' coro=<WebSocketProtocol13.write_message.<locals>.wrapper() done, defined at C:\Users\dkeya\AppData\Local\Packages\PythonSoftwareFoundation.Python.3.12_qbz5n2kfra8p0\LocalCache\local-packages\Python312\site-packages\tornado\websocket.py:1086> exception=WebSocketClosedError()>
Traceback (most recent call last):
  File "C:\Users\dkeya\AppData\Local\Packages\PythonSoftwareFoundation.Python.3.12_qbz5n2kfra8p0\LocalCache\local-packages\Python312\site-packages\tornado\websocket.py", line 1088, in wrapper
    await fut
tornado.iostream.StreamClosedError: Stream is closed

During handling of the above exception, another exception occurred:

Traceback (most recent call last):
  File "C:\Users\dkeya\AppData\Local\Packages\PythonSoftwareFoundation.Python.3.12_qbz5n2kfra8p0\LocalCache\local-packages\Python312\site-packages\tornado\websocket.py", line 1090, in wrapper
    raise WebSocketClosedError()
tornado.websocket.WebSocketClosedError
2025-07-07 08:55:42,447 - asyncio - ERROR - Task exception was never retrieved
future: <Task finished name='Task-1045' coro=<WebSocketProtocol13.write_message.<locals>.wrapper() done, defined at C:\Users\dkeya\AppData\Local\Packages\PythonSoftwareFoundation.Python.3.12_qbz5n2kfra8p0\LocalCache\local-packages\Python312\site-packages\tornado\websocket.py:1086> exception=WebSocketClosedError()>
Traceback (most recent call last):
  File "C:\Users\dkeya\AppData\Local\Packages\PythonSoftwareFoundation.Python.3.12_qbz5n2kfra8p0\LocalCache\local-packages\Python312\site-packages\tornado\websocket.py", line 1088, in wrapper
    await fut
tornado.iostream.StreamClosedError: Stream is closed

During handling of the above exception, another exception occurred:

Traceback (most recent call last):
  File "C:\Users\dkeya\AppData\Local\Packages\PythonSoftwareFoundation.Python.3.12_qbz5n2kfra8p0\LocalCache\local-packages\Python312\site-packages\tornado\websocket.py", line 1090, in wrapper
    raise WebSocketClosedError()
tornado.websocket.WebSocketClosedError
2025-07-07 08:55:42,448 - asyncio - ERROR - Task exception was never retrieved
future: <Task finished name='Task-1046' coro=<WebSocketProtocol13.write_message.<locals>.wrapper() done, defined at C:\Users\dkeya\AppData\Local\Packages\PythonSoftwareFoundation.Python.3.12_qbz5n2kfra8p0\LocalCache\local-packages\Python312\site-packages\tornado\websocket.py:1086> exception=WebSocketClosedError()>
Traceback (most recent call last):
  File "C:\Users\dkeya\AppData\Local\Packages\PythonSoftwareFoundation.Python.3.12_qbz5n2kfra8p0\LocalCache\local-packages\Python312\site-packages\tornado\websocket.py", line 1088, in wrapper
    await fut
tornado.iostream.StreamClosedError: Stream is closed

During handling of the above exception, another exception occurred:

Traceback (most recent call last):
  File "C:\Users\dkeya\AppData\Local\Packages\PythonSoftwareFoundation.Python.3.12_qbz5n2kfra8p0\LocalCache\local-packages\Python312\site-packages\tornado\websocket.py", line 1090, in wrapper
    raise WebSocketClosedError()
tornado.websocket.WebSocketClosedError
2025-07-07 08:55:42,449 - asyncio - ERROR - Task exception was never retrieved
future: <Task finished name='Task-1047' coro=<WebSocketProtocol13.write_message.<locals>.wrapper() done, defined at C:\Users\dkeya\AppData\Local\Packages\PythonSoftwareFoundation.Python.3.12_qbz5n2kfra8p0\LocalCache\local-packages\Python312\site-packages\tornado\websocket.py:1086> exception=WebSocketClosedError()>
Traceback (most recent call last):
  File "C:\Users\dkeya\AppData\Local\Packages\PythonSoftwareFoundation.Python.3.12_qbz5n2kfra8p0\LocalCache\local-packages\Python312\site-packages\tornado\websocket.py", line 1088, in wrapper
    await fut
tornado.iostream.StreamClosedError: Stream is closed

During handling of the above exception, another exception occurred:

Traceback (most recent call last):
  File "C:\Users\dkeya\AppData\Local\Packages\PythonSoftwareFoundation.Python.3.12_qbz5n2kfra8p0\LocalCache\local-packages\Python312\site-packages\tornado\websocket.py", line 1090, in wrapper
    raise WebSocketClosedError()
tornado.websocket.WebSocketClosedError
2025-07-07 08:55:42,450 - asyncio - ERROR - Task exception was never retrieved
future: <Task finished name='Task-1048' coro=<WebSocketProtocol13.write_message.<locals>.wrapper() done, defined at C:\Users\dkeya\AppData\Local\Packages\PythonSoftwareFoundation.Python.3.12_qbz5n2kfra8p0\LocalCache\local-packages\Python312\site-packages\tornado\websocket.py:1086> exception=WebSocketClosedError()>
Traceback (most recent call last):
  File "C:\Users\dkeya\AppData\Local\Packages\PythonSoftwareFoundation.Python.3.12_qbz5n2kfra8p0\LocalCache\local-packages\Python312\site-packages\tornado\websocket.py", line 1088, in wrapper
    await fut
tornado.iostream.StreamClosedError: Stream is closed

During handling of the above exception, another exception occurred:

Traceback (most recent call last):
  File "C:\Users\dkeya\AppData\Local\Packages\PythonSoftwareFoundation.Python.3.12_qbz5n2kfra8p0\LocalCache\local-packages\Python312\site-packages\tornado\websocket.py", line 1090, in wrapper
    raise WebSocketClosedError()
tornado.websocket.WebSocketClosedError
2025-07-07 08:55:42,450 - asyncio - ERROR - Task exception was never retrieved
future: <Task finished name='Task-1049' coro=<WebSocketProtocol13.write_message.<locals>.wrapper() done, defined at C:\Users\dkeya\AppData\Local\Packages\PythonSoftwareFoundation.Python.3.12_qbz5n2kfra8p0\LocalCache\local-packages\Python312\site-packages\tornado\websocket.py:1086> exception=WebSocketClosedError()>
Traceback (most recent call last):
  File "C:\Users\dkeya\AppData\Local\Packages\PythonSoftwareFoundation.Python.3.12_qbz5n2kfra8p0\LocalCache\local-packages\Python312\site-packages\tornado\websocket.py", line 1088, in wrapper
    await fut
tornado.iostream.StreamClosedError: Stream is closed

During handling of the above exception, another exception occurred:

Traceback (most recent call last):
  File "C:\Users\dkeya\AppData\Local\Packages\PythonSoftwareFoundation.Python.3.12_qbz5n2kfra8p0\LocalCache\local-packages\Python312\site-packages\tornado\websocket.py", line 1090, in wrapper
    raise WebSocketClosedError()
tornado.websocket.WebSocketClosedError
2025-07-07 08:55:42,451 - asyncio - ERROR - Task exception was never retrieved
future: <Task finished name='Task-1050' coro=<WebSocketProtocol13.write_message.<locals>.wrapper() done, defined at C:\Users\dkeya\AppData\Local\Packages\PythonSoftwareFoundation.Python.3.12_qbz5n2kfra8p0\LocalCache\local-packages\Python312\site-packages\tornado\websocket.py:1086> exception=WebSocketClosedError()>
Traceback (most recent call last):
  File "C:\Users\dkeya\AppData\Local\Packages\PythonSoftwareFoundation.Python.3.12_qbz5n2kfra8p0\LocalCache\local-packages\Python312\site-packages\tornado\websocket.py", line 1088, in wrapper
    await fut
tornado.iostream.StreamClosedError: Stream is closed

During handling of the above exception, another exception occurred:

Traceback (most recent call last):
  File "C:\Users\dkeya\AppData\Local\Packages\PythonSoftwareFoundation.Python.3.12_qbz5n2kfra8p0\LocalCache\local-packages\Python312\site-packages\tornado\websocket.py", line 1090, in wrapper
    raise WebSocketClosedError()
tornado.websocket.WebSocketClosedError
2025-07-07 08:55:42,453 - asyncio - ERROR - Task exception was never retrieved
future: <Task finished name='Task-1051' coro=<WebSocketProtocol13.write_message.<locals>.wrapper() done, defined at C:\Users\dkeya\AppData\Local\Packages\PythonSoftwareFoundation.Python.3.12_qbz5n2kfra8p0\LocalCache\local-packages\Python312\site-packages\tornado\websocket.py:1086> exception=WebSocketClosedError()>
Traceback (most recent call last):
  File "C:\Users\dkeya\AppData\Local\Packages\PythonSoftwareFoundation.Python.3.12_qbz5n2kfra8p0\LocalCache\local-packages\Python312\site-packages\tornado\websocket.py", line 1088, in wrapper
    await fut
tornado.iostream.StreamClosedError: Stream is closed

During handling of the above exception, another exception occurred:

Traceback (most recent call last):
  File "C:\Users\dkeya\AppData\Local\Packages\PythonSoftwareFoundation.Python.3.12_qbz5n2kfra8p0\LocalCache\local-packages\Python312\site-packages\tornado\websocket.py", line 1090, in wrapper
    raise WebSocketClosedError()
tornado.websocket.WebSocketClosedError
2025-07-07 08:55:42,453 - asyncio - ERROR - Task exception was never retrieved
future: <Task finished name='Task-1052' coro=<WebSocketProtocol13.write_message.<locals>.wrapper() done, defined at C:\Users\dkeya\AppData\Local\Packages\PythonSoftwareFoundation.Python.3.12_qbz5n2kfra8p0\LocalCache\local-packages\Python312\site-packages\tornado\websocket.py:1086> exception=WebSocketClosedError()>
Traceback (most recent call last):
  File "C:\Users\dkeya\AppData\Local\Packages\PythonSoftwareFoundation.Python.3.12_qbz5n2kfra8p0\LocalCache\local-packages\Python312\site-packages\tornado\websocket.py", line 1088, in wrapper
    await fut
tornado.iostream.StreamClosedError: Stream is closed

During handling of the above exception, another exception occurred:

Traceback (most recent call last):
  File "C:\Users\dkeya\AppData\Local\Packages\PythonSoftwareFoundation.Python.3.12_qbz5n2kfra8p0\LocalCache\local-packages\Python312\site-packages\tornado\websocket.py", line 1090, in wrapper
    raise WebSocketClosedError()
tornado.websocket.WebSocketClosedError
2025-07-07 08:55:42,454 - asyncio - ERROR - Task exception was never retrieved
future: <Task finished name='Task-1053' coro=<WebSocketProtocol13.write_message.<locals>.wrapper() done, defined at C:\Users\dkeya\AppData\Local\Packages\PythonSoftwareFoundation.Python.3.12_qbz5n2kfra8p0\LocalCache\local-packages\Python312\site-packages\tornado\websocket.py:1086> exception=WebSocketClosedError()>
Traceback (most recent call last):
  File "C:\Users\dkeya\AppData\Local\Packages\PythonSoftwareFoundation.Python.3.12_qbz5n2kfra8p0\LocalCache\local-packages\Python312\site-packages\tornado\websocket.py", line 1088, in wrapper
    await fut
tornado.iostream.StreamClosedError: Stream is closed

During handling of the above exception, another exception occurred:

Traceback (most recent call last):
  File "C:\Users\dkeya\AppData\Local\Packages\PythonSoftwareFoundation.Python.3.12_qbz5n2kfra8p0\LocalCache\local-packages\Python312\site-packages\tornado\websocket.py", line 1090, in wrapper
    raise WebSocketClosedError()
tornado.websocket.WebSocketClosedError
2025-07-07 08:55:42,455 - asyncio - ERROR - Task exception was never retrieved
future: <Task finished name='Task-1054' coro=<WebSocketProtocol13.write_message.<locals>.wrapper() done, defined at C:\Users\dkeya\AppData\Local\Packages\PythonSoftwareFoundation.Python.3.12_qbz5n2kfra8p0\LocalCache\local-packages\Python312\site-packages\tornado\websocket.py:1086> exception=WebSocketClosedError()>
Traceback (most recent call last):
  File "C:\Users\dkeya\AppData\Local\Packages\PythonSoftwareFoundation.Python.3.12_qbz5n2kfra8p0\LocalCache\local-packages\Python312\site-packages\tornado\websocket.py", line 1088, in wrapper
    await fut
tornado.iostream.StreamClosedError: Stream is closed

During handling of the above exception, another exception occurred:

Traceback (most recent call last):
  File "C:\Users\dkeya\AppData\Local\Packages\PythonSoftwareFoundation.Python.3.12_qbz5n2kfra8p0\LocalCache\local-packages\Python312\site-packages\tornado\websocket.py", line 1090, in wrapper
    raise WebSocketClosedError()
tornado.websocket.WebSocketClosedError
2025-07-07 08:55:42,457 - asyncio - ERROR - Task exception was never retrieved
future: <Task finished name='Task-1055' coro=<WebSocketProtocol13.write_message.<locals>.wrapper() done, defined at C:\Users\dkeya\AppData\Local\Packages\PythonSoftwareFoundation.Python.3.12_qbz5n2kfra8p0\LocalCache\local-packages\Python312\site-packages\tornado\websocket.py:1086> exception=WebSocketClosedError()>
Traceback (most recent call last):
  File "C:\Users\dkeya\AppData\Local\Packages\PythonSoftwareFoundation.Python.3.12_qbz5n2kfra8p0\LocalCache\local-packages\Python312\site-packages\tornado\websocket.py", line 1088, in wrapper
    await fut
tornado.iostream.StreamClosedError: Stream is closed

During handling of the above exception, another exception occurred:

Traceback (most recent call last):
  File "C:\Users\dkeya\AppData\Local\Packages\PythonSoftwareFoundation.Python.3.12_qbz5n2kfra8p0\LocalCache\local-packages\Python312\site-packages\tornado\websocket.py", line 1090, in wrapper
    raise WebSocketClosedError()
tornado.websocket.WebSocketClosedError
2025-07-07 08:55:42,459 - asyncio - ERROR - Task exception was never retrieved
future: <Task finished name='Task-1056' coro=<WebSocketProtocol13.write_message.<locals>.wrapper() done, defined at C:\Users\dkeya\AppData\Local\Packages\PythonSoftwareFoundation.Python.3.12_qbz5n2kfra8p0\LocalCache\local-packages\Python312\site-packages\tornado\websocket.py:1086> exception=WebSocketClosedError()>
Traceback (most recent call last):
  File "C:\Users\dkeya\AppData\Local\Packages\PythonSoftwareFoundation.Python.3.12_qbz5n2kfra8p0\LocalCache\local-packages\Python312\site-packages\tornado\websocket.py", line 1088, in wrapper
    await fut
tornado.iostream.StreamClosedError: Stream is closed

During handling of the above exception, another exception occurred:

Traceback (most recent call last):
  File "C:\Users\dkeya\AppData\Local\Packages\PythonSoftwareFoundation.Python.3.12_qbz5n2kfra8p0\LocalCache\local-packages\Python312\site-packages\tornado\websocket.py", line 1090, in wrapper
    raise WebSocketClosedError()
tornado.websocket.WebSocketClosedError
2025-07-07 08:55:42,461 - asyncio - ERROR - Task exception was never retrieved
future: <Task finished name='Task-1057' coro=<WebSocketProtocol13.write_message.<locals>.wrapper() done, defined at C:\Users\dkeya\AppData\Local\Packages\PythonSoftwareFoundation.Python.3.12_qbz5n2kfra8p0\LocalCache\local-packages\Python312\site-packages\tornado\websocket.py:1086> exception=WebSocketClosedError()>
Traceback (most recent call last):
  File "C:\Users\dkeya\AppData\Local\Packages\PythonSoftwareFoundation.Python.3.12_qbz5n2kfra8p0\LocalCache\local-packages\Python312\site-packages\tornado\websocket.py", line 1088, in wrapper
    await fut
tornado.iostream.StreamClosedError: Stream is closed

During handling of the above exception, another exception occurred:

Traceback (most recent call last):
  File "C:\Users\dkeya\AppData\Local\Packages\PythonSoftwareFoundation.Python.3.12_qbz5n2kfra8p0\LocalCache\local-packages\Python312\site-packages\tornado\websocket.py", line 1090, in wrapper
    raise WebSocketClosedError()
tornado.websocket.WebSocketClosedError
2025-07-07 08:55:42,462 - asyncio - ERROR - Task exception was never retrieved
future: <Task finished name='Task-1058' coro=<WebSocketProtocol13.write_message.<locals>.wrapper() done, defined at C:\Users\dkeya\AppData\Local\Packages\PythonSoftwareFoundation.Python.3.12_qbz5n2kfra8p0\LocalCache\local-packages\Python312\site-packages\tornado\websocket.py:1086> exception=WebSocketClosedError()>
Traceback (most recent call last):
  File "C:\Users\dkeya\AppData\Local\Packages\PythonSoftwareFoundation.Python.3.12_qbz5n2kfra8p0\LocalCache\local-packages\Python312\site-packages\tornado\websocket.py", line 1088, in wrapper
    await fut
tornado.iostream.StreamClosedError: Stream is closed

During handling of the above exception, another exception occurred:

Traceback (most recent call last):
  File "C:\Users\dkeya\AppData\Local\Packages\PythonSoftwareFoundation.Python.3.12_qbz5n2kfra8p0\LocalCache\local-packages\Python312\site-packages\tornado\websocket.py", line 1090, in wrapper
    raise WebSocketClosedError()
tornado.websocket.WebSocketClosedError
2025-07-07 09:18:07,057 - root - INFO - Renamed PROV_NAME to provider_id
2025-07-07 09:18:07,057 - root - INFO - Renamed AMOUNT to amount
2025-07-07 09:18:07,064 - root - INFO - Renamed CLAIM_PROV_DATE to date
2025-07-07 09:18:07,064 - root - INFO - Renamed CLAIM_MEMBER_NUMBER to employee_id
2025-07-07 09:18:07,065 - root - INFO - Renamed Ailment to diagnosis
2025-07-07 09:18:07,080 - root - INFO - Renamed SERVICE_DESCRIPTION to treatment
2025-07-07 09:18:07,082 - root - INFO - Renamed POL_NAME to employer
2025-07-07 09:24:08,862 - root - INFO - Renamed PROV_NAME to provider_id
2025-07-07 09:24:08,862 - root - INFO - Renamed AMOUNT to amount
2025-07-07 09:24:08,863 - root - INFO - Renamed CLAIM_PROV_DATE to date
2025-07-07 09:24:08,863 - root - INFO - Renamed CLAIM_MEMBER_NUMBER to employee_id
2025-07-07 09:24:08,864 - root - INFO - Renamed Ailment to diagnosis
2025-07-07 09:24:08,864 - root - INFO - Renamed SERVICE_DESCRIPTION to treatment
2025-07-07 09:24:08,864 - root - INFO - Renamed POL_NAME to employer
2025-07-07 09:24:08,864 - root - INFO - Renamed Department to department
2025-07-07 09:48:34,501 - root - ERROR - Data loading failed
Traceback (most recent call last):
  File "C:\Users\dkeya\Documents\projects\the Verse\demo\app.py", line 1676, in load_real_claims_data
    actual_col = get_column(df, possible_names)
                 ^^^^^^^^^^^^^^^^^^^^^^^^^^^^^^
TypeError: unhashable type: 'DataFrame'
2025-07-07 10:15:09,741 - root - ERROR - Data loading failed
Traceback (most recent call last):
  File "C:\Users\dkeya\Documents\projects\the Verse\demo\app.py", line 1676, in load_real_claims_data
    actual_col = get_column(df, possible_names)
                 ^^^^^^^^^^^^^^^^^^^^^^^^^^^^^^
TypeError: unhashable type: 'DataFrame'
2025-07-07 10:38:44,028 - root - ERROR - Data loading failed
Traceback (most recent call last):
  File "C:\Users\dkeya\Documents\projects\the Verse\demo\app.py", line 1674, in load_real_claims_data
    actual_col = get_column(df, possible_names)
                 ^^^^^^^^^^^^^^^^^^^^^^^^^^^^^^
TypeError: unhashable type: 'DataFrame'
2025-07-07 10:50:01,779 - root - ERROR - Data loading failed
Traceback (most recent call last):
  File "C:\Users\dkeya\Documents\projects\the Verse\demo\app.py", line 1686, in load_real_claims_data
    actual_col = get_column(df, possible_names)
                 ^^^^^^^^^^^^^^^^^^^^^^^^^^^^^^
TypeError: unhashable type: 'DataFrame'
2025-07-07 10:54:57,013 - root - INFO - Renamed PROV_NAME to provider_id
2025-07-07 10:54:57,014 - root - INFO - Renamed AMOUNT to amount
2025-07-07 10:54:57,014 - root - INFO - Renamed CLAIM_PROV_DATE to date
2025-07-07 10:54:57,014 - root - INFO - Renamed CLAIM_MEMBER_NUMBER to employee_id
2025-07-07 10:54:57,015 - root - INFO - Renamed Ailment to diagnosis
2025-07-07 10:54:57,015 - root - INFO - Renamed SERVICE_DESCRIPTION to treatment
2025-07-07 10:54:57,015 - root - INFO - Renamed POL_NAME to employer
2025-07-07 10:55:02,675 - __main__ - INFO - Data cleaning completed successfully
2025-07-07 10:56:07,685 - asyncio - ERROR - Task exception was never retrieved
future: <Task finished name='Task-493' coro=<WebSocketProtocol13.write_message.<locals>.wrapper() done, defined at C:\Users\dkeya\AppData\Local\Packages\PythonSoftwareFoundation.Python.3.12_qbz5n2kfra8p0\LocalCache\local-packages\Python312\site-packages\tornado\websocket.py:1086> exception=WebSocketClosedError()>
Traceback (most recent call last):
  File "C:\Users\dkeya\AppData\Local\Packages\PythonSoftwareFoundation.Python.3.12_qbz5n2kfra8p0\LocalCache\local-packages\Python312\site-packages\tornado\websocket.py", line 1088, in wrapper
    await fut
tornado.iostream.StreamClosedError: Stream is closed

During handling of the above exception, another exception occurred:

Traceback (most recent call last):
  File "C:\Users\dkeya\AppData\Local\Packages\PythonSoftwareFoundation.Python.3.12_qbz5n2kfra8p0\LocalCache\local-packages\Python312\site-packages\tornado\websocket.py", line 1090, in wrapper
    raise WebSocketClosedError()
tornado.websocket.WebSocketClosedError
2025-07-07 10:56:07,700 - asyncio - ERROR - Task exception was never retrieved
future: <Task finished name='Task-494' coro=<WebSocketProtocol13.write_message.<locals>.wrapper() done, defined at C:\Users\dkeya\AppData\Local\Packages\PythonSoftwareFoundation.Python.3.12_qbz5n2kfra8p0\LocalCache\local-packages\Python312\site-packages\tornado\websocket.py:1086> exception=WebSocketClosedError()>
Traceback (most recent call last):
  File "C:\Users\dkeya\AppData\Local\Packages\PythonSoftwareFoundation.Python.3.12_qbz5n2kfra8p0\LocalCache\local-packages\Python312\site-packages\tornado\websocket.py", line 1088, in wrapper
    await fut
tornado.iostream.StreamClosedError: Stream is closed

During handling of the above exception, another exception occurred:

Traceback (most recent call last):
  File "C:\Users\dkeya\AppData\Local\Packages\PythonSoftwareFoundation.Python.3.12_qbz5n2kfra8p0\LocalCache\local-packages\Python312\site-packages\tornado\websocket.py", line 1090, in wrapper
    raise WebSocketClosedError()
tornado.websocket.WebSocketClosedError
2025-07-07 10:56:07,700 - asyncio - ERROR - Task exception was never retrieved
future: <Task finished name='Task-497' coro=<WebSocketProtocol13.write_message.<locals>.wrapper() done, defined at C:\Users\dkeya\AppData\Local\Packages\PythonSoftwareFoundation.Python.3.12_qbz5n2kfra8p0\LocalCache\local-packages\Python312\site-packages\tornado\websocket.py:1086> exception=WebSocketClosedError()>
Traceback (most recent call last):
  File "C:\Users\dkeya\AppData\Local\Packages\PythonSoftwareFoundation.Python.3.12_qbz5n2kfra8p0\LocalCache\local-packages\Python312\site-packages\tornado\websocket.py", line 1088, in wrapper
    await fut
tornado.iostream.StreamClosedError: Stream is closed

During handling of the above exception, another exception occurred:

Traceback (most recent call last):
  File "C:\Users\dkeya\AppData\Local\Packages\PythonSoftwareFoundation.Python.3.12_qbz5n2kfra8p0\LocalCache\local-packages\Python312\site-packages\tornado\websocket.py", line 1090, in wrapper
    raise WebSocketClosedError()
tornado.websocket.WebSocketClosedError
2025-07-07 10:56:07,701 - asyncio - ERROR - Task exception was never retrieved
future: <Task finished name='Task-498' coro=<WebSocketProtocol13.write_message.<locals>.wrapper() done, defined at C:\Users\dkeya\AppData\Local\Packages\PythonSoftwareFoundation.Python.3.12_qbz5n2kfra8p0\LocalCache\local-packages\Python312\site-packages\tornado\websocket.py:1086> exception=WebSocketClosedError()>
Traceback (most recent call last):
  File "C:\Users\dkeya\AppData\Local\Packages\PythonSoftwareFoundation.Python.3.12_qbz5n2kfra8p0\LocalCache\local-packages\Python312\site-packages\tornado\websocket.py", line 1088, in wrapper
    await fut
tornado.iostream.StreamClosedError: Stream is closed

During handling of the above exception, another exception occurred:

Traceback (most recent call last):
  File "C:\Users\dkeya\AppData\Local\Packages\PythonSoftwareFoundation.Python.3.12_qbz5n2kfra8p0\LocalCache\local-packages\Python312\site-packages\tornado\websocket.py", line 1090, in wrapper
    raise WebSocketClosedError()
tornado.websocket.WebSocketClosedError
2025-07-07 10:56:07,701 - asyncio - ERROR - Task exception was never retrieved
future: <Task finished name='Task-499' coro=<WebSocketProtocol13.write_message.<locals>.wrapper() done, defined at C:\Users\dkeya\AppData\Local\Packages\PythonSoftwareFoundation.Python.3.12_qbz5n2kfra8p0\LocalCache\local-packages\Python312\site-packages\tornado\websocket.py:1086> exception=WebSocketClosedError()>
Traceback (most recent call last):
  File "C:\Users\dkeya\AppData\Local\Packages\PythonSoftwareFoundation.Python.3.12_qbz5n2kfra8p0\LocalCache\local-packages\Python312\site-packages\tornado\websocket.py", line 1088, in wrapper
    await fut
tornado.iostream.StreamClosedError: Stream is closed

During handling of the above exception, another exception occurred:

Traceback (most recent call last):
  File "C:\Users\dkeya\AppData\Local\Packages\PythonSoftwareFoundation.Python.3.12_qbz5n2kfra8p0\LocalCache\local-packages\Python312\site-packages\tornado\websocket.py", line 1090, in wrapper
    raise WebSocketClosedError()
tornado.websocket.WebSocketClosedError
2025-07-07 10:56:07,701 - asyncio - ERROR - Task exception was never retrieved
future: <Task finished name='Task-500' coro=<WebSocketProtocol13.write_message.<locals>.wrapper() done, defined at C:\Users\dkeya\AppData\Local\Packages\PythonSoftwareFoundation.Python.3.12_qbz5n2kfra8p0\LocalCache\local-packages\Python312\site-packages\tornado\websocket.py:1086> exception=WebSocketClosedError()>
Traceback (most recent call last):
  File "C:\Users\dkeya\AppData\Local\Packages\PythonSoftwareFoundation.Python.3.12_qbz5n2kfra8p0\LocalCache\local-packages\Python312\site-packages\tornado\websocket.py", line 1088, in wrapper
    await fut
tornado.iostream.StreamClosedError: Stream is closed

During handling of the above exception, another exception occurred:

Traceback (most recent call last):
  File "C:\Users\dkeya\AppData\Local\Packages\PythonSoftwareFoundation.Python.3.12_qbz5n2kfra8p0\LocalCache\local-packages\Python312\site-packages\tornado\websocket.py", line 1090, in wrapper
    raise WebSocketClosedError()
tornado.websocket.WebSocketClosedError
2025-07-07 10:56:07,702 - asyncio - ERROR - Task exception was never retrieved
future: <Task finished name='Task-501' coro=<WebSocketProtocol13.write_message.<locals>.wrapper() done, defined at C:\Users\dkeya\AppData\Local\Packages\PythonSoftwareFoundation.Python.3.12_qbz5n2kfra8p0\LocalCache\local-packages\Python312\site-packages\tornado\websocket.py:1086> exception=WebSocketClosedError()>
Traceback (most recent call last):
  File "C:\Users\dkeya\AppData\Local\Packages\PythonSoftwareFoundation.Python.3.12_qbz5n2kfra8p0\LocalCache\local-packages\Python312\site-packages\tornado\websocket.py", line 1088, in wrapper
    await fut
tornado.iostream.StreamClosedError: Stream is closed

During handling of the above exception, another exception occurred:

Traceback (most recent call last):
  File "C:\Users\dkeya\AppData\Local\Packages\PythonSoftwareFoundation.Python.3.12_qbz5n2kfra8p0\LocalCache\local-packages\Python312\site-packages\tornado\websocket.py", line 1090, in wrapper
    raise WebSocketClosedError()
tornado.websocket.WebSocketClosedError
2025-07-07 10:56:07,702 - asyncio - ERROR - Task exception was never retrieved
future: <Task finished name='Task-502' coro=<WebSocketProtocol13.write_message.<locals>.wrapper() done, defined at C:\Users\dkeya\AppData\Local\Packages\PythonSoftwareFoundation.Python.3.12_qbz5n2kfra8p0\LocalCache\local-packages\Python312\site-packages\tornado\websocket.py:1086> exception=WebSocketClosedError()>
Traceback (most recent call last):
  File "C:\Users\dkeya\AppData\Local\Packages\PythonSoftwareFoundation.Python.3.12_qbz5n2kfra8p0\LocalCache\local-packages\Python312\site-packages\tornado\websocket.py", line 1088, in wrapper
    await fut
tornado.iostream.StreamClosedError: Stream is closed

During handling of the above exception, another exception occurred:

Traceback (most recent call last):
  File "C:\Users\dkeya\AppData\Local\Packages\PythonSoftwareFoundation.Python.3.12_qbz5n2kfra8p0\LocalCache\local-packages\Python312\site-packages\tornado\websocket.py", line 1090, in wrapper
    raise WebSocketClosedError()
tornado.websocket.WebSocketClosedError
2025-07-07 10:56:07,702 - asyncio - ERROR - Task exception was never retrieved
future: <Task finished name='Task-503' coro=<WebSocketProtocol13.write_message.<locals>.wrapper() done, defined at C:\Users\dkeya\AppData\Local\Packages\PythonSoftwareFoundation.Python.3.12_qbz5n2kfra8p0\LocalCache\local-packages\Python312\site-packages\tornado\websocket.py:1086> exception=WebSocketClosedError()>
Traceback (most recent call last):
  File "C:\Users\dkeya\AppData\Local\Packages\PythonSoftwareFoundation.Python.3.12_qbz5n2kfra8p0\LocalCache\local-packages\Python312\site-packages\tornado\websocket.py", line 1088, in wrapper
    await fut
tornado.iostream.StreamClosedError: Stream is closed

During handling of the above exception, another exception occurred:

Traceback (most recent call last):
  File "C:\Users\dkeya\AppData\Local\Packages\PythonSoftwareFoundation.Python.3.12_qbz5n2kfra8p0\LocalCache\local-packages\Python312\site-packages\tornado\websocket.py", line 1090, in wrapper
    raise WebSocketClosedError()
tornado.websocket.WebSocketClosedError
2025-07-07 10:56:07,703 - asyncio - ERROR - Task exception was never retrieved
future: <Task finished name='Task-504' coro=<WebSocketProtocol13.write_message.<locals>.wrapper() done, defined at C:\Users\dkeya\AppData\Local\Packages\PythonSoftwareFoundation.Python.3.12_qbz5n2kfra8p0\LocalCache\local-packages\Python312\site-packages\tornado\websocket.py:1086> exception=WebSocketClosedError()>
Traceback (most recent call last):
  File "C:\Users\dkeya\AppData\Local\Packages\PythonSoftwareFoundation.Python.3.12_qbz5n2kfra8p0\LocalCache\local-packages\Python312\site-packages\tornado\websocket.py", line 1088, in wrapper
    await fut
tornado.iostream.StreamClosedError: Stream is closed

During handling of the above exception, another exception occurred:

Traceback (most recent call last):
  File "C:\Users\dkeya\AppData\Local\Packages\PythonSoftwareFoundation.Python.3.12_qbz5n2kfra8p0\LocalCache\local-packages\Python312\site-packages\tornado\websocket.py", line 1090, in wrapper
    raise WebSocketClosedError()
tornado.websocket.WebSocketClosedError
2025-07-07 10:56:07,703 - asyncio - ERROR - Task exception was never retrieved
future: <Task finished name='Task-505' coro=<WebSocketProtocol13.write_message.<locals>.wrapper() done, defined at C:\Users\dkeya\AppData\Local\Packages\PythonSoftwareFoundation.Python.3.12_qbz5n2kfra8p0\LocalCache\local-packages\Python312\site-packages\tornado\websocket.py:1086> exception=WebSocketClosedError()>
Traceback (most recent call last):
  File "C:\Users\dkeya\AppData\Local\Packages\PythonSoftwareFoundation.Python.3.12_qbz5n2kfra8p0\LocalCache\local-packages\Python312\site-packages\tornado\websocket.py", line 1088, in wrapper
    await fut
tornado.iostream.StreamClosedError: Stream is closed

During handling of the above exception, another exception occurred:

Traceback (most recent call last):
  File "C:\Users\dkeya\AppData\Local\Packages\PythonSoftwareFoundation.Python.3.12_qbz5n2kfra8p0\LocalCache\local-packages\Python312\site-packages\tornado\websocket.py", line 1090, in wrapper
    raise WebSocketClosedError()
tornado.websocket.WebSocketClosedError
2025-07-07 10:56:07,703 - asyncio - ERROR - Task exception was never retrieved
future: <Task finished name='Task-506' coro=<WebSocketProtocol13.write_message.<locals>.wrapper() done, defined at C:\Users\dkeya\AppData\Local\Packages\PythonSoftwareFoundation.Python.3.12_qbz5n2kfra8p0\LocalCache\local-packages\Python312\site-packages\tornado\websocket.py:1086> exception=WebSocketClosedError()>
Traceback (most recent call last):
  File "C:\Users\dkeya\AppData\Local\Packages\PythonSoftwareFoundation.Python.3.12_qbz5n2kfra8p0\LocalCache\local-packages\Python312\site-packages\tornado\websocket.py", line 1088, in wrapper
    await fut
tornado.iostream.StreamClosedError: Stream is closed

During handling of the above exception, another exception occurred:

Traceback (most recent call last):
  File "C:\Users\dkeya\AppData\Local\Packages\PythonSoftwareFoundation.Python.3.12_qbz5n2kfra8p0\LocalCache\local-packages\Python312\site-packages\tornado\websocket.py", line 1090, in wrapper
    raise WebSocketClosedError()
tornado.websocket.WebSocketClosedError
2025-07-07 10:56:07,704 - asyncio - ERROR - Task exception was never retrieved
future: <Task finished name='Task-507' coro=<WebSocketProtocol13.write_message.<locals>.wrapper() done, defined at C:\Users\dkeya\AppData\Local\Packages\PythonSoftwareFoundation.Python.3.12_qbz5n2kfra8p0\LocalCache\local-packages\Python312\site-packages\tornado\websocket.py:1086> exception=WebSocketClosedError()>
Traceback (most recent call last):
  File "C:\Users\dkeya\AppData\Local\Packages\PythonSoftwareFoundation.Python.3.12_qbz5n2kfra8p0\LocalCache\local-packages\Python312\site-packages\tornado\websocket.py", line 1088, in wrapper
    await fut
tornado.iostream.StreamClosedError: Stream is closed

During handling of the above exception, another exception occurred:

Traceback (most recent call last):
  File "C:\Users\dkeya\AppData\Local\Packages\PythonSoftwareFoundation.Python.3.12_qbz5n2kfra8p0\LocalCache\local-packages\Python312\site-packages\tornado\websocket.py", line 1090, in wrapper
    raise WebSocketClosedError()
tornado.websocket.WebSocketClosedError
2025-07-07 10:56:07,704 - asyncio - ERROR - Task exception was never retrieved
future: <Task finished name='Task-508' coro=<WebSocketProtocol13.write_message.<locals>.wrapper() done, defined at C:\Users\dkeya\AppData\Local\Packages\PythonSoftwareFoundation.Python.3.12_qbz5n2kfra8p0\LocalCache\local-packages\Python312\site-packages\tornado\websocket.py:1086> exception=WebSocketClosedError()>
Traceback (most recent call last):
  File "C:\Users\dkeya\AppData\Local\Packages\PythonSoftwareFoundation.Python.3.12_qbz5n2kfra8p0\LocalCache\local-packages\Python312\site-packages\tornado\websocket.py", line 1088, in wrapper
    await fut
tornado.iostream.StreamClosedError: Stream is closed

During handling of the above exception, another exception occurred:

Traceback (most recent call last):
  File "C:\Users\dkeya\AppData\Local\Packages\PythonSoftwareFoundation.Python.3.12_qbz5n2kfra8p0\LocalCache\local-packages\Python312\site-packages\tornado\websocket.py", line 1090, in wrapper
    raise WebSocketClosedError()
tornado.websocket.WebSocketClosedError
2025-07-07 10:56:07,704 - asyncio - ERROR - Task exception was never retrieved
future: <Task finished name='Task-509' coro=<WebSocketProtocol13.write_message.<locals>.wrapper() done, defined at C:\Users\dkeya\AppData\Local\Packages\PythonSoftwareFoundation.Python.3.12_qbz5n2kfra8p0\LocalCache\local-packages\Python312\site-packages\tornado\websocket.py:1086> exception=WebSocketClosedError()>
Traceback (most recent call last):
  File "C:\Users\dkeya\AppData\Local\Packages\PythonSoftwareFoundation.Python.3.12_qbz5n2kfra8p0\LocalCache\local-packages\Python312\site-packages\tornado\websocket.py", line 1088, in wrapper
    await fut
tornado.iostream.StreamClosedError: Stream is closed

During handling of the above exception, another exception occurred:

Traceback (most recent call last):
  File "C:\Users\dkeya\AppData\Local\Packages\PythonSoftwareFoundation.Python.3.12_qbz5n2kfra8p0\LocalCache\local-packages\Python312\site-packages\tornado\websocket.py", line 1090, in wrapper
    raise WebSocketClosedError()
tornado.websocket.WebSocketClosedError
2025-07-07 10:56:07,704 - asyncio - ERROR - Task exception was never retrieved
future: <Task finished name='Task-510' coro=<WebSocketProtocol13.write_message.<locals>.wrapper() done, defined at C:\Users\dkeya\AppData\Local\Packages\PythonSoftwareFoundation.Python.3.12_qbz5n2kfra8p0\LocalCache\local-packages\Python312\site-packages\tornado\websocket.py:1086> exception=WebSocketClosedError()>
Traceback (most recent call last):
  File "C:\Users\dkeya\AppData\Local\Packages\PythonSoftwareFoundation.Python.3.12_qbz5n2kfra8p0\LocalCache\local-packages\Python312\site-packages\tornado\websocket.py", line 1088, in wrapper
    await fut
tornado.iostream.StreamClosedError: Stream is closed

During handling of the above exception, another exception occurred:

Traceback (most recent call last):
  File "C:\Users\dkeya\AppData\Local\Packages\PythonSoftwareFoundation.Python.3.12_qbz5n2kfra8p0\LocalCache\local-packages\Python312\site-packages\tornado\websocket.py", line 1090, in wrapper
    raise WebSocketClosedError()
tornado.websocket.WebSocketClosedError
2025-07-07 10:56:07,706 - asyncio - ERROR - Task exception was never retrieved
future: <Task finished name='Task-511' coro=<WebSocketProtocol13.write_message.<locals>.wrapper() done, defined at C:\Users\dkeya\AppData\Local\Packages\PythonSoftwareFoundation.Python.3.12_qbz5n2kfra8p0\LocalCache\local-packages\Python312\site-packages\tornado\websocket.py:1086> exception=WebSocketClosedError()>
Traceback (most recent call last):
  File "C:\Users\dkeya\AppData\Local\Packages\PythonSoftwareFoundation.Python.3.12_qbz5n2kfra8p0\LocalCache\local-packages\Python312\site-packages\tornado\websocket.py", line 1088, in wrapper
    await fut
tornado.iostream.StreamClosedError: Stream is closed

During handling of the above exception, another exception occurred:

Traceback (most recent call last):
  File "C:\Users\dkeya\AppData\Local\Packages\PythonSoftwareFoundation.Python.3.12_qbz5n2kfra8p0\LocalCache\local-packages\Python312\site-packages\tornado\websocket.py", line 1090, in wrapper
    raise WebSocketClosedError()
tornado.websocket.WebSocketClosedError
2025-07-07 11:00:06,045 - root - INFO - Renamed PROV_NAME to provider_id
2025-07-07 11:00:06,046 - root - INFO - Renamed AMOUNT to amount
2025-07-07 11:00:06,048 - root - INFO - Renamed CLAIM_PROV_DATE to date
2025-07-07 11:00:06,049 - root - INFO - Renamed CLAIM_MEMBER_NUMBER to employee_id
2025-07-07 11:00:06,050 - root - INFO - Renamed Ailment to diagnosis
2025-07-07 11:00:06,051 - root - INFO - Renamed SERVICE_DESCRIPTION to treatment
2025-07-07 11:00:06,061 - root - INFO - Renamed POL_NAME to employer
2025-07-07 11:00:13,773 - __main__ - INFO - Data cleaning completed successfully
2025-07-07 11:02:21,411 - asyncio - ERROR - Task exception was never retrieved
future: <Task finished name='Task-640' coro=<WebSocketProtocol13.write_message.<locals>.wrapper() done, defined at C:\Users\dkeya\AppData\Local\Packages\PythonSoftwareFoundation.Python.3.12_qbz5n2kfra8p0\LocalCache\local-packages\Python312\site-packages\tornado\websocket.py:1086> exception=WebSocketClosedError()>
Traceback (most recent call last):
  File "C:\Users\dkeya\AppData\Local\Packages\PythonSoftwareFoundation.Python.3.12_qbz5n2kfra8p0\LocalCache\local-packages\Python312\site-packages\tornado\websocket.py", line 1088, in wrapper
    await fut
tornado.iostream.StreamClosedError: Stream is closed

During handling of the above exception, another exception occurred:

Traceback (most recent call last):
  File "C:\Users\dkeya\AppData\Local\Packages\PythonSoftwareFoundation.Python.3.12_qbz5n2kfra8p0\LocalCache\local-packages\Python312\site-packages\tornado\websocket.py", line 1090, in wrapper
    raise WebSocketClosedError()
tornado.websocket.WebSocketClosedError
2025-07-07 11:02:21,412 - asyncio - ERROR - Task exception was never retrieved
future: <Task finished name='Task-643' coro=<WebSocketProtocol13.write_message.<locals>.wrapper() done, defined at C:\Users\dkeya\AppData\Local\Packages\PythonSoftwareFoundation.Python.3.12_qbz5n2kfra8p0\LocalCache\local-packages\Python312\site-packages\tornado\websocket.py:1086> exception=WebSocketClosedError()>
Traceback (most recent call last):
  File "C:\Users\dkeya\AppData\Local\Packages\PythonSoftwareFoundation.Python.3.12_qbz5n2kfra8p0\LocalCache\local-packages\Python312\site-packages\tornado\websocket.py", line 1088, in wrapper
    await fut
tornado.iostream.StreamClosedError: Stream is closed

During handling of the above exception, another exception occurred:

Traceback (most recent call last):
  File "C:\Users\dkeya\AppData\Local\Packages\PythonSoftwareFoundation.Python.3.12_qbz5n2kfra8p0\LocalCache\local-packages\Python312\site-packages\tornado\websocket.py", line 1090, in wrapper
    raise WebSocketClosedError()
tornado.websocket.WebSocketClosedError
2025-07-07 11:02:21,412 - asyncio - ERROR - Task exception was never retrieved
future: <Task finished name='Task-646' coro=<WebSocketProtocol13.write_message.<locals>.wrapper() done, defined at C:\Users\dkeya\AppData\Local\Packages\PythonSoftwareFoundation.Python.3.12_qbz5n2kfra8p0\LocalCache\local-packages\Python312\site-packages\tornado\websocket.py:1086> exception=WebSocketClosedError()>
Traceback (most recent call last):
  File "C:\Users\dkeya\AppData\Local\Packages\PythonSoftwareFoundation.Python.3.12_qbz5n2kfra8p0\LocalCache\local-packages\Python312\site-packages\tornado\websocket.py", line 1088, in wrapper
    await fut
tornado.iostream.StreamClosedError: Stream is closed

During handling of the above exception, another exception occurred:

Traceback (most recent call last):
  File "C:\Users\dkeya\AppData\Local\Packages\PythonSoftwareFoundation.Python.3.12_qbz5n2kfra8p0\LocalCache\local-packages\Python312\site-packages\tornado\websocket.py", line 1090, in wrapper
    raise WebSocketClosedError()
tornado.websocket.WebSocketClosedError
2025-07-07 11:02:21,413 - asyncio - ERROR - Task exception was never retrieved
future: <Task finished name='Task-649' coro=<WebSocketProtocol13.write_message.<locals>.wrapper() done, defined at C:\Users\dkeya\AppData\Local\Packages\PythonSoftwareFoundation.Python.3.12_qbz5n2kfra8p0\LocalCache\local-packages\Python312\site-packages\tornado\websocket.py:1086> exception=WebSocketClosedError()>
Traceback (most recent call last):
  File "C:\Users\dkeya\AppData\Local\Packages\PythonSoftwareFoundation.Python.3.12_qbz5n2kfra8p0\LocalCache\local-packages\Python312\site-packages\tornado\websocket.py", line 1088, in wrapper
    await fut
tornado.iostream.StreamClosedError: Stream is closed

During handling of the above exception, another exception occurred:

Traceback (most recent call last):
  File "C:\Users\dkeya\AppData\Local\Packages\PythonSoftwareFoundation.Python.3.12_qbz5n2kfra8p0\LocalCache\local-packages\Python312\site-packages\tornado\websocket.py", line 1090, in wrapper
    raise WebSocketClosedError()
tornado.websocket.WebSocketClosedError
2025-07-07 11:02:21,415 - asyncio - ERROR - Task exception was never retrieved
future: <Task finished name='Task-652' coro=<WebSocketProtocol13.write_message.<locals>.wrapper() done, defined at C:\Users\dkeya\AppData\Local\Packages\PythonSoftwareFoundation.Python.3.12_qbz5n2kfra8p0\LocalCache\local-packages\Python312\site-packages\tornado\websocket.py:1086> exception=WebSocketClosedError()>
Traceback (most recent call last):
  File "C:\Users\dkeya\AppData\Local\Packages\PythonSoftwareFoundation.Python.3.12_qbz5n2kfra8p0\LocalCache\local-packages\Python312\site-packages\tornado\websocket.py", line 1088, in wrapper
    await fut
tornado.iostream.StreamClosedError: Stream is closed

During handling of the above exception, another exception occurred:

Traceback (most recent call last):
  File "C:\Users\dkeya\AppData\Local\Packages\PythonSoftwareFoundation.Python.3.12_qbz5n2kfra8p0\LocalCache\local-packages\Python312\site-packages\tornado\websocket.py", line 1090, in wrapper
    raise WebSocketClosedError()
tornado.websocket.WebSocketClosedError
2025-07-07 11:02:21,416 - asyncio - ERROR - Task exception was never retrieved
future: <Task finished name='Task-655' coro=<WebSocketProtocol13.write_message.<locals>.wrapper() done, defined at C:\Users\dkeya\AppData\Local\Packages\PythonSoftwareFoundation.Python.3.12_qbz5n2kfra8p0\LocalCache\local-packages\Python312\site-packages\tornado\websocket.py:1086> exception=WebSocketClosedError()>
Traceback (most recent call last):
  File "C:\Users\dkeya\AppData\Local\Packages\PythonSoftwareFoundation.Python.3.12_qbz5n2kfra8p0\LocalCache\local-packages\Python312\site-packages\tornado\websocket.py", line 1088, in wrapper
    await fut
tornado.iostream.StreamClosedError: Stream is closed

During handling of the above exception, another exception occurred:

Traceback (most recent call last):
  File "C:\Users\dkeya\AppData\Local\Packages\PythonSoftwareFoundation.Python.3.12_qbz5n2kfra8p0\LocalCache\local-packages\Python312\site-packages\tornado\websocket.py", line 1090, in wrapper
    raise WebSocketClosedError()
tornado.websocket.WebSocketClosedError
2025-07-07 11:02:21,417 - asyncio - ERROR - Task exception was never retrieved
future: <Task finished name='Task-658' coro=<WebSocketProtocol13.write_message.<locals>.wrapper() done, defined at C:\Users\dkeya\AppData\Local\Packages\PythonSoftwareFoundation.Python.3.12_qbz5n2kfra8p0\LocalCache\local-packages\Python312\site-packages\tornado\websocket.py:1086> exception=WebSocketClosedError()>
Traceback (most recent call last):
  File "C:\Users\dkeya\AppData\Local\Packages\PythonSoftwareFoundation.Python.3.12_qbz5n2kfra8p0\LocalCache\local-packages\Python312\site-packages\tornado\websocket.py", line 1088, in wrapper
    await fut
tornado.iostream.StreamClosedError: Stream is closed

During handling of the above exception, another exception occurred:

Traceback (most recent call last):
  File "C:\Users\dkeya\AppData\Local\Packages\PythonSoftwareFoundation.Python.3.12_qbz5n2kfra8p0\LocalCache\local-packages\Python312\site-packages\tornado\websocket.py", line 1090, in wrapper
    raise WebSocketClosedError()
tornado.websocket.WebSocketClosedError
2025-07-07 11:02:21,434 - asyncio - ERROR - Task exception was never retrieved
future: <Task finished name='Task-661' coro=<WebSocketProtocol13.write_message.<locals>.wrapper() done, defined at C:\Users\dkeya\AppData\Local\Packages\PythonSoftwareFoundation.Python.3.12_qbz5n2kfra8p0\LocalCache\local-packages\Python312\site-packages\tornado\websocket.py:1086> exception=WebSocketClosedError()>
Traceback (most recent call last):
  File "C:\Users\dkeya\AppData\Local\Packages\PythonSoftwareFoundation.Python.3.12_qbz5n2kfra8p0\LocalCache\local-packages\Python312\site-packages\tornado\websocket.py", line 1088, in wrapper
    await fut
tornado.iostream.StreamClosedError: Stream is closed

During handling of the above exception, another exception occurred:

Traceback (most recent call last):
  File "C:\Users\dkeya\AppData\Local\Packages\PythonSoftwareFoundation.Python.3.12_qbz5n2kfra8p0\LocalCache\local-packages\Python312\site-packages\tornado\websocket.py", line 1090, in wrapper
    raise WebSocketClosedError()
tornado.websocket.WebSocketClosedError
2025-07-07 11:02:21,436 - asyncio - ERROR - Task exception was never retrieved
future: <Task finished name='Task-664' coro=<WebSocketProtocol13.write_message.<locals>.wrapper() done, defined at C:\Users\dkeya\AppData\Local\Packages\PythonSoftwareFoundation.Python.3.12_qbz5n2kfra8p0\LocalCache\local-packages\Python312\site-packages\tornado\websocket.py:1086> exception=WebSocketClosedError()>
Traceback (most recent call last):
  File "C:\Users\dkeya\AppData\Local\Packages\PythonSoftwareFoundation.Python.3.12_qbz5n2kfra8p0\LocalCache\local-packages\Python312\site-packages\tornado\websocket.py", line 1088, in wrapper
    await fut
tornado.iostream.StreamClosedError: Stream is closed

During handling of the above exception, another exception occurred:

Traceback (most recent call last):
  File "C:\Users\dkeya\AppData\Local\Packages\PythonSoftwareFoundation.Python.3.12_qbz5n2kfra8p0\LocalCache\local-packages\Python312\site-packages\tornado\websocket.py", line 1090, in wrapper
    raise WebSocketClosedError()
tornado.websocket.WebSocketClosedError
2025-07-07 11:02:21,439 - asyncio - ERROR - Task exception was never retrieved
future: <Task finished name='Task-667' coro=<WebSocketProtocol13.write_message.<locals>.wrapper() done, defined at C:\Users\dkeya\AppData\Local\Packages\PythonSoftwareFoundation.Python.3.12_qbz5n2kfra8p0\LocalCache\local-packages\Python312\site-packages\tornado\websocket.py:1086> exception=WebSocketClosedError()>
Traceback (most recent call last):
  File "C:\Users\dkeya\AppData\Local\Packages\PythonSoftwareFoundation.Python.3.12_qbz5n2kfra8p0\LocalCache\local-packages\Python312\site-packages\tornado\websocket.py", line 1088, in wrapper
    await fut
tornado.iostream.StreamClosedError: Stream is closed

During handling of the above exception, another exception occurred:

Traceback (most recent call last):
  File "C:\Users\dkeya\AppData\Local\Packages\PythonSoftwareFoundation.Python.3.12_qbz5n2kfra8p0\LocalCache\local-packages\Python312\site-packages\tornado\websocket.py", line 1090, in wrapper
    raise WebSocketClosedError()
tornado.websocket.WebSocketClosedError
2025-07-07 11:02:21,442 - asyncio - ERROR - Task exception was never retrieved
future: <Task finished name='Task-670' coro=<WebSocketProtocol13.write_message.<locals>.wrapper() done, defined at C:\Users\dkeya\AppData\Local\Packages\PythonSoftwareFoundation.Python.3.12_qbz5n2kfra8p0\LocalCache\local-packages\Python312\site-packages\tornado\websocket.py:1086> exception=WebSocketClosedError()>
Traceback (most recent call last):
  File "C:\Users\dkeya\AppData\Local\Packages\PythonSoftwareFoundation.Python.3.12_qbz5n2kfra8p0\LocalCache\local-packages\Python312\site-packages\tornado\websocket.py", line 1088, in wrapper
    await fut
tornado.iostream.StreamClosedError: Stream is closed

During handling of the above exception, another exception occurred:

Traceback (most recent call last):
  File "C:\Users\dkeya\AppData\Local\Packages\PythonSoftwareFoundation.Python.3.12_qbz5n2kfra8p0\LocalCache\local-packages\Python312\site-packages\tornado\websocket.py", line 1090, in wrapper
    raise WebSocketClosedError()
tornado.websocket.WebSocketClosedError
2025-07-07 11:02:21,444 - asyncio - ERROR - Task exception was never retrieved
future: <Task finished name='Task-673' coro=<WebSocketProtocol13.write_message.<locals>.wrapper() done, defined at C:\Users\dkeya\AppData\Local\Packages\PythonSoftwareFoundation.Python.3.12_qbz5n2kfra8p0\LocalCache\local-packages\Python312\site-packages\tornado\websocket.py:1086> exception=WebSocketClosedError()>
Traceback (most recent call last):
  File "C:\Users\dkeya\AppData\Local\Packages\PythonSoftwareFoundation.Python.3.12_qbz5n2kfra8p0\LocalCache\local-packages\Python312\site-packages\tornado\websocket.py", line 1088, in wrapper
    await fut
tornado.iostream.StreamClosedError: Stream is closed

During handling of the above exception, another exception occurred:

Traceback (most recent call last):
  File "C:\Users\dkeya\AppData\Local\Packages\PythonSoftwareFoundation.Python.3.12_qbz5n2kfra8p0\LocalCache\local-packages\Python312\site-packages\tornado\websocket.py", line 1090, in wrapper
    raise WebSocketClosedError()
tornado.websocket.WebSocketClosedError
2025-07-07 11:02:21,447 - asyncio - ERROR - Task exception was never retrieved
future: <Task finished name='Task-676' coro=<WebSocketProtocol13.write_message.<locals>.wrapper() done, defined at C:\Users\dkeya\AppData\Local\Packages\PythonSoftwareFoundation.Python.3.12_qbz5n2kfra8p0\LocalCache\local-packages\Python312\site-packages\tornado\websocket.py:1086> exception=WebSocketClosedError()>
Traceback (most recent call last):
  File "C:\Users\dkeya\AppData\Local\Packages\PythonSoftwareFoundation.Python.3.12_qbz5n2kfra8p0\LocalCache\local-packages\Python312\site-packages\tornado\websocket.py", line 1088, in wrapper
    await fut
tornado.iostream.StreamClosedError: Stream is closed

During handling of the above exception, another exception occurred:

Traceback (most recent call last):
  File "C:\Users\dkeya\AppData\Local\Packages\PythonSoftwareFoundation.Python.3.12_qbz5n2kfra8p0\LocalCache\local-packages\Python312\site-packages\tornado\websocket.py", line 1090, in wrapper
    raise WebSocketClosedError()
tornado.websocket.WebSocketClosedError
2025-07-07 11:02:21,448 - asyncio - ERROR - Task exception was never retrieved
future: <Task finished name='Task-679' coro=<WebSocketProtocol13.write_message.<locals>.wrapper() done, defined at C:\Users\dkeya\AppData\Local\Packages\PythonSoftwareFoundation.Python.3.12_qbz5n2kfra8p0\LocalCache\local-packages\Python312\site-packages\tornado\websocket.py:1086> exception=WebSocketClosedError()>
Traceback (most recent call last):
  File "C:\Users\dkeya\AppData\Local\Packages\PythonSoftwareFoundation.Python.3.12_qbz5n2kfra8p0\LocalCache\local-packages\Python312\site-packages\tornado\websocket.py", line 1088, in wrapper
    await fut
tornado.iostream.StreamClosedError: Stream is closed

During handling of the above exception, another exception occurred:

Traceback (most recent call last):
  File "C:\Users\dkeya\AppData\Local\Packages\PythonSoftwareFoundation.Python.3.12_qbz5n2kfra8p0\LocalCache\local-packages\Python312\site-packages\tornado\websocket.py", line 1090, in wrapper
    raise WebSocketClosedError()
tornado.websocket.WebSocketClosedError
2025-07-07 11:02:21,448 - asyncio - ERROR - Task exception was never retrieved
future: <Task finished name='Task-682' coro=<WebSocketProtocol13.write_message.<locals>.wrapper() done, defined at C:\Users\dkeya\AppData\Local\Packages\PythonSoftwareFoundation.Python.3.12_qbz5n2kfra8p0\LocalCache\local-packages\Python312\site-packages\tornado\websocket.py:1086> exception=WebSocketClosedError()>
Traceback (most recent call last):
  File "C:\Users\dkeya\AppData\Local\Packages\PythonSoftwareFoundation.Python.3.12_qbz5n2kfra8p0\LocalCache\local-packages\Python312\site-packages\tornado\websocket.py", line 1088, in wrapper
    await fut
tornado.iostream.StreamClosedError: Stream is closed

During handling of the above exception, another exception occurred:

Traceback (most recent call last):
  File "C:\Users\dkeya\AppData\Local\Packages\PythonSoftwareFoundation.Python.3.12_qbz5n2kfra8p0\LocalCache\local-packages\Python312\site-packages\tornado\websocket.py", line 1090, in wrapper
    raise WebSocketClosedError()
tornado.websocket.WebSocketClosedError
2025-07-07 11:02:21,451 - asyncio - ERROR - Task exception was never retrieved
future: <Task finished name='Task-686' coro=<WebSocketProtocol13.write_message.<locals>.wrapper() done, defined at C:\Users\dkeya\AppData\Local\Packages\PythonSoftwareFoundation.Python.3.12_qbz5n2kfra8p0\LocalCache\local-packages\Python312\site-packages\tornado\websocket.py:1086> exception=WebSocketClosedError()>
Traceback (most recent call last):
  File "C:\Users\dkeya\AppData\Local\Packages\PythonSoftwareFoundation.Python.3.12_qbz5n2kfra8p0\LocalCache\local-packages\Python312\site-packages\tornado\websocket.py", line 1088, in wrapper
    await fut
tornado.iostream.StreamClosedError: Stream is closed

During handling of the above exception, another exception occurred:

Traceback (most recent call last):
  File "C:\Users\dkeya\AppData\Local\Packages\PythonSoftwareFoundation.Python.3.12_qbz5n2kfra8p0\LocalCache\local-packages\Python312\site-packages\tornado\websocket.py", line 1090, in wrapper
    raise WebSocketClosedError()
tornado.websocket.WebSocketClosedError
2025-07-07 11:02:21,452 - asyncio - ERROR - Task exception was never retrieved
future: <Task finished name='Task-687' coro=<WebSocketProtocol13.write_message.<locals>.wrapper() done, defined at C:\Users\dkeya\AppData\Local\Packages\PythonSoftwareFoundation.Python.3.12_qbz5n2kfra8p0\LocalCache\local-packages\Python312\site-packages\tornado\websocket.py:1086> exception=WebSocketClosedError()>
Traceback (most recent call last):
  File "C:\Users\dkeya\AppData\Local\Packages\PythonSoftwareFoundation.Python.3.12_qbz5n2kfra8p0\LocalCache\local-packages\Python312\site-packages\tornado\websocket.py", line 1088, in wrapper
    await fut
tornado.iostream.StreamClosedError: Stream is closed

During handling of the above exception, another exception occurred:

Traceback (most recent call last):
  File "C:\Users\dkeya\AppData\Local\Packages\PythonSoftwareFoundation.Python.3.12_qbz5n2kfra8p0\LocalCache\local-packages\Python312\site-packages\tornado\websocket.py", line 1090, in wrapper
    raise WebSocketClosedError()
tornado.websocket.WebSocketClosedError
2025-07-07 12:09:36,319 - root - ERROR - Data loading failed
Traceback (most recent call last):
  File "C:\Users\dkeya\Documents\projects\the Verse\demo\app.py", line 1686, in load_real_claims_data
    actual_col = get_column(df, possible_names)
                 ^^^^^^^^^^^^^^^^^^^^^^^^^^^^^^
TypeError: unhashable type: 'DataFrame'
2025-07-07 12:47:33,951 - root - ERROR - Data loading failed
Traceback (most recent call last):
  File "C:\Users\dkeya\Documents\projects\the Verse\demo\app.py", line 1686, in load_real_claims_data
    actual_col = get_column(df, possible_names)
                 ^^^^^^^^^^^^^^^^^^^^^^^^^^^^^^
TypeError: unhashable type: 'DataFrame'
2025-07-07 13:44:28,061 - root - ERROR - Data loading failed for safaricom_limited_line_items-6mths.xlsx
Traceback (most recent call last):
  File "C:\Users\dkeya\Documents\projects\the Verse\demo\app.py", line 1700, in load_real_claims_data
    actual_col = get_column(tuple(df.columns), possible_names)
                 ^^^^^^^^^^^^^^^^^^^^^^^^^^^^^^^^^^^^^^^^^^^^^
TypeError: unhashable type: 'list'
2025-07-07 13:48:10,213 - root - ERROR - Data loading failed for safaricom_limited_line_items-6mths.xlsx
Traceback (most recent call last):
  File "C:\Users\dkeya\Documents\projects\the Verse\demo\app.py", line 1700, in load_real_claims_data
    actual_col = get_column(tuple(df.columns), possible_names)
                 ^^^^^^^^^^^^^^^^^^^^^^^^^^^^^^^^^^^^^^^^^^^^^
TypeError: unhashable type: 'list'
2025-07-08 15:04:02,223 - root - ERROR - Data loading failed for client_data.xlsx
Traceback (most recent call last):
  File "C:\Users\dkeya\Documents\projects\the Verse\demo\app.py", line 1700, in load_real_claims_data
    actual_col = get_column(tuple(df.columns), possible_names)
                 ^^^^^^^^^^^^^^^^^^^^^^^^^^^^^^^^^^^^^^^^^^^^^
TypeError: unhashable type: 'list'
2025-07-08 16:50:55,247 - root - INFO - Renamed PROV_NAME to provider_id
2025-07-08 16:50:55,250 - root - INFO - Renamed AMOUNT to amount
2025-07-08 16:50:55,251 - root - INFO - Renamed CLAIM_PROV_DATE to date
2025-07-08 16:50:55,253 - root - INFO - Renamed CLAIM_MEMBER_NUMBER to employee_id
2025-07-08 16:50:55,254 - root - INFO - Renamed Ailment to diagnosis
2025-07-08 16:50:55,256 - root - INFO - Renamed SERVICE_DESCRIPTION to treatment
2025-07-08 16:50:55,257 - root - INFO - Renamed POL_NAME to employer
2025-07-08 16:50:55,259 - root - INFO - Renamed Department to department
2025-07-08 16:51:06,194 - __main__ - INFO - Data cleaning completed successfully
2025-07-08 17:22:48,955 - root - INFO - Renamed PROV_NAME to provider_id
2025-07-08 17:22:48,956 - root - INFO - Renamed AMOUNT to amount
2025-07-08 17:22:48,956 - root - INFO - Renamed CLAIM_PROV_DATE to date
2025-07-08 17:22:48,957 - root - INFO - Renamed CLAIM_MEMBER_NUMBER to employee_id
2025-07-08 17:22:48,958 - root - INFO - Renamed Ailment to diagnosis
2025-07-08 17:22:48,959 - root - INFO - Renamed SERVICE_DESCRIPTION to treatment
2025-07-08 17:22:48,959 - root - INFO - Renamed POL_NAME to employer
2025-07-08 17:22:48,959 - root - INFO - Renamed Department to department
2025-07-08 17:23:20,499 - root - INFO - Renamed PROV_NAME to provider_id
2025-07-08 17:23:20,499 - root - INFO - Renamed AMOUNT to amount
2025-07-08 17:23:20,499 - root - INFO - Renamed CLAIM_PROV_DATE to date
2025-07-08 17:23:20,499 - root - INFO - Renamed CLAIM_MEMBER_NUMBER to employee_id
2025-07-08 17:23:20,499 - root - INFO - Renamed Ailment to diagnosis
2025-07-08 17:23:20,499 - root - INFO - Renamed SERVICE_DESCRIPTION to treatment
2025-07-08 17:23:20,499 - root - INFO - Renamed POL_NAME to employer
2025-07-08 17:23:20,499 - root - INFO - Renamed Department to department
2025-07-08 17:24:12,414 - root - INFO - Renamed PROV_NAME to provider_id
2025-07-08 17:24:12,414 - root - INFO - Renamed AMOUNT to amount
2025-07-08 17:24:12,414 - root - INFO - Renamed CLAIM_PROV_DATE to date
2025-07-08 17:24:12,422 - root - INFO - Renamed CLAIM_MEMBER_NUMBER to employee_id
2025-07-08 17:24:12,422 - root - INFO - Renamed Ailment to diagnosis
2025-07-08 17:24:12,422 - root - INFO - Renamed SERVICE_DESCRIPTION to treatment
2025-07-08 17:24:12,422 - root - INFO - Renamed POL_NAME to employer
2025-07-08 17:24:12,422 - root - INFO - Renamed Department to department
2025-07-08 17:28:13,744 - root - INFO - Renamed PROV_NAME to provider_id
2025-07-08 17:28:13,752 - root - INFO - Renamed AMOUNT to amount
2025-07-08 17:28:13,752 - root - INFO - Renamed CLAIM_PROV_DATE to date
2025-07-08 17:28:13,754 - root - INFO - Renamed CLAIM_MEMBER_NUMBER to employee_id
2025-07-08 17:28:13,754 - root - INFO - Renamed Ailment to diagnosis
2025-07-08 17:28:13,754 - root - INFO - Renamed SERVICE_DESCRIPTION to treatment
2025-07-08 17:28:13,754 - root - INFO - Renamed POL_NAME to employer
2025-07-08 17:28:13,754 - root - INFO - Renamed Department to department
2025-07-08 17:28:49,358 - root - INFO - Renamed PROV_NAME to provider_id
2025-07-08 17:28:49,359 - root - INFO - Renamed AMOUNT to amount
2025-07-08 17:28:49,360 - root - INFO - Renamed CLAIM_PROV_DATE to date
2025-07-08 17:28:49,360 - root - INFO - Renamed CLAIM_MEMBER_NUMBER to employee_id
2025-07-08 17:28:49,361 - root - INFO - Renamed Ailment to diagnosis
2025-07-08 17:28:49,362 - root - INFO - Renamed SERVICE_DESCRIPTION to treatment
2025-07-08 17:28:49,371 - root - INFO - Renamed POL_NAME to employer
2025-07-08 17:28:49,371 - root - INFO - Renamed Department to department
2025-07-08 17:29:02,808 - __main__ - INFO - Data cleaning completed successfully
2025-07-08 17:31:58,297 - root - ERROR - Fraud detection failed: Failed to add fraud_flag column
2025-07-08 17:43:16,759 - root - INFO - Renamed PROV_NAME to provider_id
2025-07-08 17:43:16,759 - root - INFO - Renamed AMOUNT to amount
2025-07-08 17:43:16,759 - root - INFO - Renamed CLAIM_PROV_DATE to date
2025-07-08 17:43:16,767 - root - INFO - Renamed CLAIM_MEMBER_NUMBER to employee_id
2025-07-08 17:43:16,767 - root - INFO - Renamed Ailment to diagnosis
2025-07-08 17:43:16,768 - root - INFO - Renamed SERVICE_DESCRIPTION to treatment
2025-07-08 17:43:16,768 - root - INFO - Renamed POL_NAME to employer
2025-07-08 17:43:16,769 - root - INFO - Renamed Department to department
2025-07-08 18:51:08,523 - root - INFO - Renamed PROV_NAME to provider_id
2025-07-08 18:51:08,523 - root - INFO - Renamed AMOUNT to amount
2025-07-08 18:51:08,523 - root - INFO - Renamed CLAIM_PROV_DATE to date
2025-07-08 18:51:08,532 - root - INFO - Renamed CLAIM_MEMBER_NUMBER to employee_id
2025-07-08 18:51:08,532 - root - INFO - Renamed Ailment to diagnosis
2025-07-08 18:51:08,532 - root - INFO - Renamed SERVICE_DESCRIPTION to treatment
2025-07-08 18:51:08,532 - root - INFO - Renamed POL_NAME to employer
2025-07-08 18:51:08,532 - root - INFO - Renamed Department to department
2025-07-08 18:51:29,913 - root - INFO - Renamed PROV_NAME to provider_id
2025-07-08 18:51:29,914 - root - INFO - Renamed AMOUNT to amount
2025-07-08 18:51:29,914 - root - INFO - Renamed CLAIM_PROV_DATE to date
2025-07-08 18:51:29,914 - root - INFO - Renamed CLAIM_MEMBER_NUMBER to employee_id
2025-07-08 18:51:29,915 - root - INFO - Renamed Ailment to diagnosis
2025-07-08 18:51:29,915 - root - INFO - Renamed SERVICE_DESCRIPTION to treatment
2025-07-08 18:51:29,915 - root - INFO - Renamed POL_NAME to employer
2025-07-08 18:51:29,915 - root - INFO - Renamed Department to department
2025-07-08 18:51:38,927 - __main__ - INFO - Data cleaning completed successfully
2025-07-08 18:53:42,108 - root - ERROR - Fraud detection failed: Failed to add fraud_flag column
2025-07-08 19:05:51,594 - root - INFO - Renamed PROV_NAME to provider_id
2025-07-08 19:05:51,594 - root - INFO - Renamed AMOUNT to amount
2025-07-08 19:05:51,595 - root - INFO - Renamed CLAIM_PROV_DATE to date
2025-07-08 19:05:51,595 - root - INFO - Renamed CLAIM_MEMBER_NUMBER to employee_id
2025-07-08 19:05:51,595 - root - INFO - Renamed Ailment to diagnosis
2025-07-08 19:05:51,596 - root - INFO - Renamed SERVICE_DESCRIPTION to treatment
2025-07-08 19:05:51,596 - root - INFO - Renamed POL_NAME to employer
2025-07-08 19:05:51,596 - root - INFO - Renamed Department to department
2025-07-10 10:22:05,068 - root - INFO - Renamed PROV_NAME to provider_id
2025-07-10 10:22:05,069 - root - INFO - Renamed AMOUNT to amount
2025-07-10 10:22:05,069 - root - INFO - Renamed CLAIM_PROV_DATE to date
2025-07-10 10:22:05,070 - root - INFO - Renamed CLAIM_MEMBER_NUMBER to employee_id
2025-07-10 10:22:05,070 - root - INFO - Renamed Ailment to diagnosis
2025-07-10 10:22:05,070 - root - INFO - Renamed SERVICE_DESCRIPTION to treatment
2025-07-10 10:22:05,071 - root - INFO - Renamed POL_NAME to employer
2025-07-10 10:22:05,071 - root - INFO - Renamed Department to department
2025-07-10 10:22:13,810 - __main__ - INFO - Data cleaning completed successfully
2025-07-10 10:23:28,707 - root - ERROR - Fraud detection failed: Failed to add fraud_flag column
2025-07-12 09:29:39,605 - root - INFO - Renamed PROV_NAME to provider_id
2025-07-12 09:29:39,606 - root - INFO - Renamed AMOUNT to amount
2025-07-12 09:29:39,607 - root - INFO - Renamed CLAIM_PROV_DATE to date
2025-07-12 09:29:39,608 - root - INFO - Renamed CLAIM_MEMBER_NUMBER to employee_id
2025-07-12 09:29:39,608 - root - INFO - Renamed Ailment to diagnosis
2025-07-12 09:29:39,609 - root - INFO - Renamed SERVICE_DESCRIPTION to treatment
2025-07-12 09:29:39,609 - root - INFO - Renamed POL_NAME to employer
2025-07-12 09:29:39,609 - root - INFO - Renamed Department to department
2025-07-13 18:47:29,936 - root - INFO - Renamed PROV_NAME to provider_id
2025-07-13 18:47:29,936 - root - INFO - Renamed AMOUNT to amount
2025-07-13 18:47:29,936 - root - INFO - Renamed CLAIM_PROV_DATE to date
2025-07-13 18:47:29,936 - root - INFO - Renamed CLAIM_MEMBER_NUMBER to employee_id
2025-07-13 18:47:29,936 - root - INFO - Renamed Ailment to diagnosis
2025-07-13 18:47:29,936 - root - INFO - Renamed SERVICE_DESCRIPTION to treatment
2025-07-13 18:47:29,936 - root - INFO - Renamed POL_NAME to employer
2025-07-13 18:47:29,942 - root - INFO - Renamed Department to department
2025-07-13 18:47:38,889 - __main__ - INFO - Data cleaning completed successfully
2025-07-13 18:48:52,134 - root - ERROR - Fraud detection failed: Failed to add fraud_flag column
2025-07-16 09:21:32,763 - root - INFO - Renamed PROV_NAME to provider_id
2025-07-16 09:21:32,763 - root - INFO - Renamed AMOUNT to amount
2025-07-16 09:21:32,770 - root - INFO - Renamed CLAIM_PROV_DATE to date
2025-07-16 09:21:32,770 - root - INFO - Renamed CLAIM_MEMBER_NUMBER to employee_id
2025-07-16 09:21:32,771 - root - INFO - Renamed Ailment to diagnosis
2025-07-16 09:21:32,771 - root - INFO - Renamed SERVICE_DESCRIPTION to treatment
2025-07-16 09:21:32,772 - root - INFO - Renamed POL_NAME to employer
2025-07-16 09:21:32,773 - root - INFO - Renamed Department to department
2025-07-16 09:21:51,247 - __main__ - INFO - Data cleaning completed successfully
2025-07-16 09:28:35,393 - root - ERROR - Fraud detection failed: Failed to add fraud_flag column
2025-07-16 09:50:15,120 - root - INFO - Renamed PROV_NAME to provider_id
2025-07-16 09:50:15,122 - root - INFO - Renamed AMOUNT to amount
2025-07-16 09:50:15,124 - root - INFO - Renamed CLAIM_PROV_DATE to date
2025-07-16 09:50:15,125 - root - INFO - Renamed CLAIM_MEMBER_NUMBER to employee_id
2025-07-16 09:50:15,125 - root - INFO - Renamed Ailment to diagnosis
2025-07-16 09:50:15,125 - root - INFO - Renamed SERVICE_DESCRIPTION to treatment
2025-07-16 09:50:15,125 - root - INFO - Renamed POL_NAME to employer
2025-07-16 09:50:15,130 - root - INFO - Renamed Department to department
2025-07-16 09:50:31,410 - __main__ - INFO - Data cleaning completed successfully
2025-07-16 09:52:08,259 - root - ERROR - Fraud detection failed: Failed to add fraud_flag column
2025-07-16 09:55:47,263 - root - INFO - Renamed PROV_NAME to provider_id
2025-07-16 09:55:47,263 - root - INFO - Renamed AMOUNT to amount
2025-07-16 09:55:47,263 - root - INFO - Renamed CLAIM_PROV_DATE to date
2025-07-16 09:55:47,265 - root - INFO - Renamed CLAIM_MEMBER_NUMBER to employee_id
2025-07-16 09:55:47,265 - root - INFO - Renamed Ailment to diagnosis
2025-07-16 09:55:47,265 - root - INFO - Renamed SERVICE_DESCRIPTION to treatment
2025-07-16 09:55:47,265 - root - INFO - Renamed POL_NAME to employer
2025-07-16 09:55:47,265 - root - INFO - Renamed Department to department
2025-07-18 18:20:13,613 - root - INFO - Renamed PROV_NAME to provider_id
2025-07-18 18:20:13,618 - root - INFO - Renamed AMOUNT to amount
2025-07-18 18:20:13,620 - root - INFO - Renamed CLAIM_PROV_DATE to date
2025-07-18 18:20:13,621 - root - INFO - Renamed CLAIM_MEMBER_NUMBER to employee_id
2025-07-18 18:20:13,621 - root - INFO - Renamed Ailment to diagnosis
2025-07-18 18:20:13,621 - root - INFO - Renamed SERVICE_DESCRIPTION to treatment
2025-07-18 18:20:13,621 - root - INFO - Renamed POL_NAME to employer
2025-07-18 18:20:13,621 - root - INFO - Renamed Department to department
2025-07-18 18:21:20,157 - __main__ - INFO - Data cleaning completed successfully
2025-07-18 18:28:18,947 - __main__ - INFO - Data cleaning completed successfully
2025-07-18 18:36:43,787 - root - ERROR - Fraud detection failed: Failed to add fraud_flag column
2025-07-20 16:34:17,518 - root - INFO - Renamed PROV_NAME to provider_id
2025-07-20 16:34:17,518 - root - INFO - Renamed AMOUNT to amount
2025-07-20 16:34:17,518 - root - INFO - Renamed CLAIM_PROV_DATE to date
2025-07-20 16:34:17,518 - root - INFO - Renamed CLAIM_MEMBER_NUMBER to employee_id
2025-07-20 16:34:17,518 - root - INFO - Renamed Ailment to diagnosis
2025-07-20 16:34:17,518 - root - INFO - Renamed SERVICE_DESCRIPTION to treatment
2025-07-20 16:34:17,518 - root - INFO - Renamed POL_NAME to employer
2025-07-20 16:34:17,518 - root - INFO - Renamed Department to department
2025-07-20 16:38:32,626 - __main__ - INFO - Data cleaning completed successfully
2025-07-20 16:52:42,171 - root - ERROR - Fraud detection failed: Failed to add fraud_flag column
2025-07-20 17:07:38,613 - root - INFO - Renamed PROV_NAME to provider_id
2025-07-20 17:07:38,615 - root - INFO - Renamed AMOUNT to amount
2025-07-20 17:07:38,616 - root - INFO - Renamed CLAIM_PROV_DATE to date
2025-07-20 17:07:38,617 - root - INFO - Renamed CLAIM_MEMBER_NUMBER to employee_id
2025-07-20 17:07:38,617 - root - INFO - Renamed Ailment to diagnosis
2025-07-20 17:07:38,617 - root - INFO - Renamed SERVICE_DESCRIPTION to treatment
2025-07-20 17:07:38,617 - root - INFO - Renamed POL_NAME to employer
2025-07-20 17:07:38,620 - root - INFO - Renamed Department to department
2025-07-20 17:07:45,417 - __main__ - INFO - Data cleaning completed successfully
2025-07-21 16:08:39,961 - root - INFO - Renamed PROV_NAME to provider_id
2025-07-21 16:08:39,961 - root - INFO - Renamed AMOUNT to amount
2025-07-21 16:08:39,961 - root - INFO - Renamed CLAIM_PROV_DATE to date
2025-07-21 16:08:39,961 - root - INFO - Renamed CLAIM_MEMBER_NUMBER to employee_id
2025-07-21 16:08:39,961 - root - INFO - Renamed Ailment to diagnosis
2025-07-21 16:08:39,961 - root - INFO - Renamed SERVICE_DESCRIPTION to treatment
2025-07-21 16:08:39,961 - root - INFO - Renamed POL_NAME to employer
2025-07-21 16:08:39,961 - root - INFO - Renamed Department to department
2025-07-21 16:09:10,229 - __main__ - INFO - Data cleaning completed successfully
2025-07-23 22:09:29,929 - root - INFO - Renamed PROV_NAME to provider_id
2025-07-23 22:09:29,932 - root - INFO - Renamed AMOUNT to amount
2025-07-23 22:09:29,933 - root - INFO - Renamed CLAIM_PROV_DATE to date
2025-07-23 22:09:29,933 - root - INFO - Renamed CLAIM_MEMBER_NUMBER to employee_id
2025-07-23 22:09:29,935 - root - INFO - Renamed Ailment to diagnosis
2025-07-23 22:09:29,935 - root - INFO - Renamed SERVICE_DESCRIPTION to treatment
2025-07-23 22:09:29,937 - root - INFO - Renamed POL_NAME to employer
2025-07-23 22:09:29,937 - root - INFO - Renamed Department to department
2025-07-23 22:09:44,423 - __main__ - INFO - Data cleaning completed successfully
2025-07-23 22:13:31,412 - root - ERROR - Fraud detection failed: Failed to add fraud_flag column
2025-07-25 16:21:21,421 - root - INFO - Renamed PROV_NAME to provider_id
2025-07-25 16:21:21,421 - root - INFO - Renamed AMOUNT to amount
2025-07-25 16:21:21,421 - root - INFO - Renamed CLAIM_PROV_DATE to date
2025-07-25 16:21:21,425 - root - INFO - Renamed CLAIM_MEMBER_NUMBER to employee_id
2025-07-25 16:21:21,425 - root - INFO - Renamed Ailment to diagnosis
2025-07-25 16:21:21,425 - root - INFO - Renamed SERVICE_DESCRIPTION to treatment
2025-07-25 16:21:21,427 - root - INFO - Renamed POL_NAME to employer
2025-07-25 16:21:21,428 - root - INFO - Renamed Department to department
2025-07-25 16:22:10,783 - __main__ - INFO - Data cleaning completed successfully
2025-07-25 16:35:17,146 - root - ERROR - Fraud detection failed: Failed to add fraud_flag column
2025-07-27 13:25:42,430 - root - INFO - Renamed PROV_NAME to provider_id
2025-07-27 13:25:42,437 - root - INFO - Renamed AMOUNT to amount
2025-07-27 13:25:42,437 - root - INFO - Renamed CLAIM_PROV_DATE to date
2025-07-27 13:25:42,437 - root - INFO - Renamed CLAIM_MEMBER_NUMBER to employee_id
2025-07-27 13:25:42,437 - root - INFO - Renamed Ailment to diagnosis
2025-07-27 13:25:42,437 - root - INFO - Renamed SERVICE_DESCRIPTION to treatment
2025-07-27 13:25:42,437 - root - INFO - Renamed POL_NAME to employer
2025-07-27 13:25:42,437 - root - INFO - Renamed Department to department
2025-07-27 13:25:48,900 - __main__ - INFO - Data cleaning completed successfully
2025-07-27 13:27:52,322 - __main__ - WARNING - Filled missing columns: {'Department'}
2025-07-27 13:28:39,641 - root - ERROR - Fraud detection failed: Failed to add fraud_flag column
2025-07-27 13:30:37,942 - root - ERROR - Failed to load client data: Unable to locate credentials
2025-08-16 12:12:42,440 - root - ERROR - Error loading claims data: 'int' object has no attribute 'encode'
2025-08-16 12:12:54,703 - root - ERROR - Error loading claims data: 'int' object has no attribute 'encode'
2025-08-16 12:13:09,787 - root - ERROR - Error loading claims data: 'float' object has no attribute 'encode'
2025-08-16 12:20:46,624 - root - INFO - Renamed Name to provider_id
2025-08-16 12:20:46,626 - root - INFO - Renamed TotalClaimed to amount
2025-08-16 12:20:46,627 - root - INFO - Renamed ClaimDate to date
2025-08-16 12:20:46,628 - root - INFO - Renamed MemberID to employee_id
2025-08-16 12:20:46,629 - root - INFO - Renamed Ailment to diagnosis
2025-08-16 12:20:46,633 - root - INFO - Renamed Benefit to treatment
2025-08-16 12:21:10,001 - __main__ - INFO - Data cleaning completed successfully
2025-08-16 12:21:24,255 - __main__ - INFO - Data cleaning completed successfully
2025-08-16 12:21:34,635 - __main__ - ERROR - Training failed: With n_samples=0, test_size=0.2 and train_size=None, the resulting train set will be empty. Adjust any of the aforementioned parameters.
2025-08-16 12:37:13,538 - root - INFO - Renamed Name to provider_id
2025-08-16 12:37:13,538 - root - INFO - Renamed TotalClaimed to amount
2025-08-16 12:37:13,538 - root - INFO - Renamed ClaimDate to date
2025-08-16 12:37:13,538 - root - INFO - Renamed MemberID to employee_id
2025-08-16 12:37:13,549 - root - INFO - Renamed Ailment to diagnosis
2025-08-16 12:37:13,555 - root - INFO - Renamed Benefit to treatment
2025-08-16 12:37:18,752 - __main__ - INFO - Data cleaning completed successfully
2025-08-16 12:39:46,151 - root - INFO - Renamed PROV_NAME to provider_id
2025-08-16 12:39:46,154 - root - INFO - Renamed AMOUNT to amount
2025-08-16 12:39:46,155 - root - INFO - Renamed CLAIM_PROV_DATE to date
2025-08-16 12:39:46,155 - root - INFO - Renamed CLAIM_MEMBER_NUMBER to employee_id
2025-08-16 12:39:46,156 - root - INFO - Renamed Ailment to diagnosis
2025-08-16 12:39:46,157 - root - INFO - Renamed SERVICE_DESCRIPTION to treatment
2025-08-16 12:39:46,159 - root - INFO - Renamed POL_NAME to employer
2025-08-16 12:39:46,164 - root - INFO - Renamed Department to department
2025-08-16 12:39:54,672 - __main__ - INFO - Data cleaning completed successfully
2025-08-16 13:08:27,262 - root - INFO - Renamed Name to provider_id
2025-08-16 13:08:27,264 - root - INFO - Renamed TotalClaimed to amount
2025-08-16 13:08:27,265 - root - INFO - Renamed ClaimDate to date
2025-08-16 13:08:27,266 - root - INFO - Renamed MemberID to employee_id
2025-08-16 13:08:27,269 - root - INFO - Renamed Ailment to diagnosis
2025-08-16 13:08:27,270 - root - INFO - Renamed Benefit to treatment
2025-08-16 13:08:38,428 - __main__ - INFO - Data cleaning completed successfully
2025-08-16 13:08:47,438 - root - INFO - Renamed PROV_NAME to provider_id
2025-08-16 13:08:47,438 - root - INFO - Renamed AMOUNT to amount
2025-08-16 13:08:47,443 - root - INFO - Renamed CLAIM_PROV_DATE to date
2025-08-16 13:08:47,444 - root - INFO - Renamed CLAIM_MEMBER_NUMBER to employee_id
2025-08-16 13:08:47,445 - root - INFO - Renamed Ailment to diagnosis
2025-08-16 13:08:47,445 - root - INFO - Renamed SERVICE_DESCRIPTION to treatment
2025-08-16 13:08:47,445 - root - INFO - Renamed POL_NAME to employer
2025-08-16 13:08:47,445 - root - INFO - Renamed Department to department
2025-08-16 13:08:57,172 - __main__ - INFO - Data cleaning completed successfully
2025-08-16 14:37:52,166 - root - INFO - Renamed PROV_NAME to provider_id
2025-08-16 14:37:52,167 - root - INFO - Renamed AMOUNT to amount
2025-08-16 14:37:52,167 - root - INFO - Renamed CLAIM_PROV_DATE to date
2025-08-16 14:37:52,169 - root - INFO - Renamed CLAIM_MEMBER_NUMBER to employee_id
2025-08-16 14:37:52,169 - root - INFO - Renamed Ailment to diagnosis
2025-08-16 14:37:52,169 - root - INFO - Renamed SERVICE_DESCRIPTION to treatment
2025-08-16 14:37:52,169 - root - INFO - Renamed POL_NAME to employer
2025-08-16 14:37:52,169 - root - INFO - Renamed Department to department
2025-08-16 14:55:57,864 - __main__ - INFO - Data cleaning completed successfully
2025-08-16 17:04:04,394 - root - INFO - Renamed PROV_NAME to provider_id
2025-08-16 17:04:04,395 - root - INFO - Renamed AMOUNT to amount
2025-08-16 17:04:04,395 - root - INFO - Renamed CLAIM_PROV_DATE to date
2025-08-16 17:04:04,395 - root - INFO - Renamed CLAIM_MEMBER_NUMBER to employee_id
2025-08-16 17:04:04,396 - root - INFO - Renamed Ailment to diagnosis
2025-08-16 17:04:04,396 - root - INFO - Renamed SERVICE_DESCRIPTION to treatment
2025-08-16 17:04:04,396 - root - INFO - Renamed POL_NAME to employer
2025-08-16 17:04:04,396 - root - INFO - Renamed Department to department
2025-08-16 17:04:12,589 - __main__ - INFO - Data cleaning completed successfully
2025-08-17 10:21:53,595 - root - INFO - Renamed PROV_NAME to provider_id
2025-08-17 10:21:53,604 - root - INFO - Renamed AMOUNT to amount
2025-08-17 10:21:53,604 - root - INFO - Renamed CLAIM_PROV_DATE to date
2025-08-17 10:21:53,605 - root - INFO - Renamed CLAIM_MEMBER_NUMBER to employee_id
2025-08-17 10:21:53,605 - root - INFO - Renamed Ailment to diagnosis
2025-08-17 10:21:53,605 - root - INFO - Renamed SERVICE_DESCRIPTION to treatment
2025-08-17 10:21:53,605 - root - INFO - Renamed POL_NAME to employer
2025-08-17 10:21:53,609 - root - INFO - Renamed Department to department
2025-08-17 10:22:23,520 - __main__ - INFO - Data cleaning completed successfully
2025-08-18 22:25:55,798 - root - INFO - Renamed PROV_NAME to provider_id
2025-08-18 22:25:55,801 - root - INFO - Renamed AMOUNT to amount
2025-08-18 22:25:55,802 - root - INFO - Renamed CLAIM_PROV_DATE to date
2025-08-18 22:25:55,805 - root - INFO - Renamed CLAIM_MEMBER_NUMBER to employee_id
2025-08-18 22:25:55,810 - root - INFO - Renamed Ailment to diagnosis
2025-08-18 22:25:55,811 - root - INFO - Renamed SERVICE_DESCRIPTION to treatment
2025-08-18 22:25:55,812 - root - INFO - Renamed POL_NAME to employer
2025-08-18 22:25:55,813 - root - INFO - Renamed Department to department
2025-08-18 22:26:08,742 - __main__ - INFO - Data cleaning completed successfully
2025-08-21 12:06:41,397 - root - INFO - Renamed PROV_NAME to provider_id
2025-08-21 12:06:41,399 - root - INFO - Renamed AMOUNT to amount
2025-08-21 12:06:41,400 - root - INFO - Renamed CLAIM_PROV_DATE to date
2025-08-21 12:06:41,400 - root - INFO - Renamed CLAIM_MEMBER_NUMBER to employee_id
2025-08-21 12:06:41,400 - root - INFO - Renamed Ailment to diagnosis
2025-08-21 12:06:41,400 - root - INFO - Renamed SERVICE_DESCRIPTION to treatment
2025-08-21 12:06:41,400 - root - INFO - Renamed POL_NAME to employer
2025-08-21 12:06:41,400 - root - INFO - Renamed Department to department
2025-08-21 12:07:11,191 - __main__ - INFO - Data cleaning completed successfully
2025-08-21 12:28:10,360 - root - INFO - Renamed PROV_NAME to provider_id
2025-08-21 12:28:10,361 - root - INFO - Renamed AMOUNT to amount
2025-08-21 12:28:10,361 - root - INFO - Renamed CLAIM_PROV_DATE to date
2025-08-21 12:28:10,361 - root - INFO - Renamed CLAIM_MEMBER_NUMBER to employee_id
2025-08-21 12:28:10,361 - root - INFO - Renamed Ailment to diagnosis
2025-08-21 12:28:10,362 - root - INFO - Renamed SERVICE_DESCRIPTION to treatment
2025-08-21 12:28:10,362 - root - INFO - Renamed POL_NAME to employer
2025-08-21 12:28:10,362 - root - INFO - Renamed Department to department
2025-08-21 12:28:51,363 - __main__ - INFO - Data cleaning completed successfully
